Workbook
Name AGOSTO: #REF!
Name AGOSTO: #REF!
Name AGOSTO: #REF!
Name AGOSTO: #REF!
Name AGOSTO: #REF!
Name AGOSTO: #REF!
Name AGOSTO: #REF!
Name AGOSTO: #REF!
Name AGOSTO: #REF!
Name AGOSTO: #REF!
Name AGOSTO: #REF!
Name AGOSTO: #REF!
Name AGOSTO: #REF!
Name AGOSTO: #REF!
Name AGOSTO: #REF!
Name WinCal4: #REF!
Name WinCal4: #REF!
Name WinCal4: #REF!
Name WinCal4: #REF!
Name WinCal4: #REF!
Name WinCal4: #REF!
Name WinCal4: #REF!
Name WinCal4: #REF!
Name WinCal4: #REF!
Name WinCal4: #REF!
Name WinCal4: #REF!
Name WinCal4: #REF!
Name WinCal4: #REF!
Name WinCal4: #REF!
Name WinCal4: #REF!
Name WinCal5: #REF!
Name WinCal5: #REF!
Name WinCal5: #REF!
Name WinCal5: #REF!
Name WinCal5: #REF!
Name WinCal5: #REF!
Name WinCal5: #REF!
Name WinCal5: #REF!
Name WinCal5: #REF!
Name WinCal5: #REF!
Name WinCal5: #REF!
Name WinCal5: #REF!
Name WinCal5: #REF!
Name WinCal5: #REF!
Name WinCal5: #REF!
Name WinCalendar_Calendar_4: #REF!
Name WinCalendar_Calendar_4: #REF!
Name WinCalendar_Calendar_4: #REF!
Name WinCalendar_Calendar_4: #REF!
Name WinCalendar_Calendar_4: #REF!
Name WinCalendar_Calendar_4: #REF!
Name WinCalendar_Calendar_4: #REF!
Name WinCalendar_Calendar_4: #REF!
Name WinCalendar_Calendar_4: #REF!
Name WinCalendar_Calendar_4: #REF!
Name WinCalendar_Calendar_4: #REF!
Name WinCalendar_Calendar_4: #REF!
Name WinCalendar_Calendar_4: #REF!
Name WinCalendar_Calendar_4: #REF!
Name WinCalendar_Calendar_4: #REF!

Sheet 2026_RECEITA_BRASANTOS
B1: BRASANTOS SERVIÇOS ESPECIALIZADOS
B2: RECEITA
B4: CNAE-Fiscal: | D4: N812140000 _ LIMPEZA EM PREDIOS E EM DOMICILIOS
B5: ATIVIDADE MUNICIPIO: | D5: 710 - 7.10 - Limpeza, manutenção e conservação de vias e logradouros
B7: ANO: | C7: 2026
B8: CLIENTE: | C8: BRASANTOS | E8: REGIME DE TRIBUTAÇÃO: | F8: LUCRO PRESUMIDO
B9: CNPJ: | C9: 23.372.953.0001-86
B10: ENDEREÇO: | C10: ÁGUAS CLARAS
B11: TOTAL | C11: =E254 -> 92319
B13: COMP | C13: NF | D13: CLIENTE | E13: VALOR TOTAL DOS SERVIÇOS | F13: MATERIAS | G13: EQUIPAMENTOS | H13: VALE TRANSPORTE | Q13: VALE ALIMENTAÇÃO | Z13: UNIFORME | AI13: TOTAL BASE RETENÇÃO INSS | AJ13: BASE CÁCULO INSS | AK13: RETENÇÃO DESTACADO NA NF | AR13: TOTAL RETENÇÃO NF | AS13: VALOR LIQUIDO DA NOTA FISCAL
H14: 44H/S | L14: 12 X 36 | P14: TOTAL | Q14: 44H/S | U14: 12 X 36 | Y14: TOTAL | Z14: 44H/S | AD14: 12 X 36 | AH14: TOTAL | AK14: GPS 2632 | AL14: IRRJ 2089 | AM14: CSLL 2372 | AN14: COFINS 2172 | AO14: PIS 8109 | AP14: ISSQN 1732 | AQ14: TOTAL
H15: QTDE | I15: $ UNIT | J15: DIAS | K15: TOTAL | L15: QTDE | M15: $ UNIT | N15: DIAS | O15: TOTAL | Q15: QTDE | R15: $ UNIT | S15: DIAS | T15: TOTAL | U15: QTDE | V15: $ UNIT | W15: DIAS | X15: TOTAL | Z15: QTDE | AA15: $ UNIT | AB15: ANO | AC15: TOTAL | AD15: QTDE | AE15: $ UNIT | AF15: ANO | AG15: TOTAL | AJ15: % | AK15: 0.11 | AL15: 0.01 | AM15: 0.01 | AN15: 0.03 | AO15: 0.0065 | AP15: 0.05 | AQ15: =SUBTOTAL(9,AL15:AP15) -> 0.1065 | AR15: =AK15+AQ15 -> 0.2165
B17: 01/24 | C17: 152 | D17: AHSERC | E17: 5458 | F17: 774.5 | G17: 326.16667 | H17: 1 | I17: 16 | J17: 26 | K17: =H17*I17*J17 -> 416 | L17: 0 | M17: 0 | N17: 0 | O17: =L17*M17*N17 -> 0 | P17: =K17+O17 -> 416 | Q17: 1 | R17: 40.5 | S17: 26 | T17: =Q17*R17*S17 -> 1053 | U17: 0 | V17: 0 | W17: 0 | X17: =U17*V17*W17 -> 0 | Y17: =T17+X17 -> 1053 | Z17: 1 | AA17: 80 | AB17: 1 | AC17: =Z17*AA17*AB17 -> 80 | AD17: 0 | AE17: 0 | AF17: 0 | AG17: =AD17*AE17*AF17 -> 0 | AH17: =AC17+AG17 -> 80 | AI17: =F17+G17+P17+Y17+AH17 -> 2649.6667 | AJ17: =AI17/E17 -> 0.48546476 | AK17: 308.91667 | AL17: 54.58 | AM17: 54.58 | AN17: 163.74 | AO17: 35.477 | AP17: 272.9 | AQ17: =SUM(AL17:AP17) -> 581.277 | AR17: =AK17+AQ17 -> 890.19367 | AS17: =E17-AR17 -> 4567.8063
B18: 01/24 | C18: 153 | D18: RIO PARANÃ | E18: 14796 | F18: 2186.2 | G18: 0 | H18: 1 | I18: 16 | J18: 26 | K18: =H18*I18*J18 -> 416 | L18: 2 | M18: 16 | N18: 16 | O18: =L18*M18*N18 -> 512 | P18: =K18+O18 -> 928 | Q18: 1 | R18: 40.5 | S18: 26 | T18: =Q18*R18*S18 -> 1053 | U18: 2 | V18: 40.5 | W18: 16 | X18: =U18*V18*W18 -> 1296 | Y18: =T18+X18 -> 2349 | Z18: 1 | AA18: 80 | AB18: 1 | AC18: =Z18*AA18*AB18 -> 80 | AD18: 2 | AE18: 80 | AF18: 1 | AG18: =AD18*AE18*AF18 -> 160 | AH18: =AC18+AG18 -> 240 | AI18: =F18+G18+P18+Y18+AH18 -> 5703.2 | AJ18: =AI18/E18 -> 0.38545553 | AK18: 1000.208 | AL18: 147.96 | AM18: 147.96 | AN18: 443.88 | AO18: 96.174 | AP18: 739.8 | AQ18: =SUM(AL18:AP18) -> 1575.774 | AR18: =AK18+AQ18 -> 2575.982 | AS18: =E18-AR18 -> 12220.018
B19: 01/24 | C19: 154 | D19: VANESSA | E19: 4800 | F19: 781.45 | G19: 0 | H19: 1 | I19: 16 | J19: 26 | K19: =H19*I19*J19 -> 416 | L19: 0 | M19: 0 | N19: 0 | O19: =L19*M19*N19 -> 0 | P19: =K19+O19 -> 416 | Q19: 1 | R19: 40.5 | S19: 26 | T19: =Q19*R19*S19 -> 1053 | U19: 0 | V19: 0 | W19: 0 | X19: =U19*V19*W19 -> 0 | Y19: =T19+X19 -> 1053 | Z19: 1 | AA19: 80 | AB19: 1 | AC19: =Z19*AA19*AB19 -> 80 | AD19: 0 | AE19: 0 | AF19: 0 | AG19: =AD19*AE19*AF19 -> 0 | AH19: =AC19+AG19 -> 80 | AI19: =F19+G19+P19+Y19+AH19 -> 2330.45 | AJ19: =AI19/E19 -> 0.48551042 | AK19: 271.6505 | AL19: 48 | AM19: 48 | AN19: 144 | AO19: 31.2 | AP19: 240 | AQ19: =SUM(AL19:AP19) -> 511.2 | AR19: =AK19+AQ19 -> 782.8505 | AS19: =E19-AR19 -> 4017.1495
B20: 01/24 | C20: 155 | D20: ATLANTIS | E20: 24300 | F20: 3221.55 | G20: 0 | H20: 3 | I20: 16 | J20: 26 | K20: =H20*I20*J20 -> 1248 | L20: 2 | M20: 16 | N20: =16+4 -> 20 | O20: =L20*M20*N20 -> 640 | P20: =K20+O20 -> 1888 | Q20: 3 | R20: 40.5 | S20: 26 | T20: =Q20*R20*S20 -> 3159 | U20: 2 | V20: 40.5 | W20: =16+4 -> 20 | X20: =U20*V20*W20 -> 1620 | Y20: =T20+X20 -> 4779 | Z20: 3 | AA20: 60 | AB20: 1 | AC20: =Z20*AA20*AB20 -> 180 | AD20: 3 | AE20: 90 | AF20: 1 | AG20: =AD20*AE20*AF20 -> 270 | AH20: =AC20+AG20 -> 450 | AI20: =F20+G20+P20+Y20+AH20 -> 10338.55 | AJ20: =AI20/E20 -> 0.42545473 | AK20: 1535.7595 | AL20: 243 | AM20: 243 | AN20: 729 | AO20: 157.95 | AP20: 1215 | AQ20: =SUM(AL20:AP20) -> 2587.95 | AR20: =AK20+AQ20 -> 4123.7095 | AS20: =E20-AR20 -> 20176.29
B21: 01/24 | C21: 156 | D21: QUATRO ESTAÇÕES 509 | E21: 5199 | F21: 833.1 | G21: 0 | H21: 1 | I21: 16 | J21: 26 | K21: =H21*I21*J21 -> 416 | L21: 0 | M21: 0 | N21: 0 | O21: =L21*M21*N21 -> 0 | P21: =K21+O21 -> 416 | Q21: 1 | R21: 40.5 | S21: 26 | T21: =Q21*R21*S21 -> 1053 | U21: 0 | V21: 0 | W21: 0 | X21: =U21*V21*W21 -> 0 | Y21: =T21+X21 -> 1053 | Z21: 1 | AA21: 80 | AB21: 1 | AC21: =Z21*AA21*AB21 -> 80 | AD21: 0 | AE21: 0 | AF21: 0 | AG21: =AD21*AE21*AF21 -> 0 | AH21: =AC21+AG21 -> 80 | AI21: =F21+G21+P21+Y21+AH21 -> 2382.1 | AJ21: =AI21/E21 -> 0.45818427 | AK21: 309.859 | AL21: 51.99 | AM21: 51.99 | AN21: 155.97 | AO21: 33.7935 | AP21: 259.95 | AQ21: =SUM(AL21:AP21) -> 553.6935 | AR21: =AK21+AQ21 -> 863.5525 | AS21: =E21-AR21 -> 4335.4475
B22: 01/24 | C22: 157 | D22: QUATRO ESTAÇÕES 507 | E22: 5377 | F22: 914.6 | G22: 0 | H22: 1 | I22: 16 | J22: 26 | K22: =H22*I22*J22 -> 416 | L22: 0 | M22: 0 | N22: 0 | O22: =L22*M22*N22 -> 0 | P22: =K22+O22 -> 416 | Q22: 1 | R22: 40.5 | S22: 26 | T22: =Q22*R22*S22 -> 1053 | U22: 0 | V22: 0 | W22: 0 | X22: =U22*V22*W22 -> 0 | Y22: =T22+X22 -> 1053 | Z22: 1 | AA22: 80 | AB22: 1 | AC22: =Z22*AA22*AB22 -> 80 | AD22: 0 | AE22: 0 | AF22: 0 | AG22: =AD22*AE22*AF22 -> 0 | AH22: =AC22+AG22 -> 80 | AI22: =F22+G22+P22+Y22+AH22 -> 2463.6 | AJ22: =AI22/E22 -> 0.4581737 | AK22: 320.474 | AL22: 53.77 | AM22: 53.77 | AN22: 161.31 | AO22: 34.9505 | AP22: 268.85 | AQ22: =SUM(AL22:AP22) -> 572.6505 | AR22: =AK22+AQ22 -> 893.1245 | AS22: =E22-AR22 -> 4483.8755
B23: 01/24 | C23: 158 | D23: TAJ MAHAL | E23: 33786.42 | F23: 2796.15 | G23: 0 | H23: 1 | I23: 10 | J23: 26 | K23: =H23*I23*J23 -> 260 | L23: 2 | M23: 19.25 | N23: 16 | O23: =L23*M23*N23 -> 616 | P23: =K23+O23 -> 876 | Q23: 4 | R23: 18.2 | S23: 22 | T23: =Q23*R23*S23 -> 1601.6 | U23: 2 | V23: 18.2 | W23: 15.5 | X23: =U23*V23*W23 -> 564.2 | Y23: =T23+X23 -> 2165.8 | Z23: 4 | AA23: =90/12 -> 7.5 | AB23: 2 | AC23: =Z23*AA23*AB23 -> 60 | AD23: 2 | AE23: =90/12 -> 7.5 | AF23: 2 | AG23: =AD23*AE23*AF23 -> 30 | AH23: =AC23+AG23 -> 90 | AI23: =F23+G23+P23+Y23+AH23 -> 5927.95 | AJ23: =AI23/E23 -> 0.17545363 | AK23: 3064.4317 | AL23: 337.8642 | AM23: 337.8642 | AN23: 1013.5926 | AO23: 219.61173 | AP23: 0 | AQ23: =SUM(AL23:AP23) -> 1908.9327 | AR23: =AK23+AQ23 -> 4973.3644 | AS23: =E23-AR23 -> 28813.056
B24: 01/24 | C24: 159 | D24: DIRECIONAL_ ÁGUA BRANCA_SOBRADINHO | E24: 23824.9 | F24: 0 | G24: 0 | H24: 0 | I24: 0 | J24: 0 | K24: =H24*I24*J24 -> 0 | L24: 0 | M24: 0 | N24: 0 | O24: =L24*M24*N24 -> 0 | P24: =K24+O24 -> 0 | Q24: 0 | R24: 0 | S24: 0 | T24: =Q24*R24*S24 -> 0 | U24: 0 | V24: 0 | W24: 0 | X24: =U24*V24*W24 -> 0 | Y24: =T24+X24 -> 0 | Z24: 0 | AA24: 0 | AB24: 0 | AC24: =Z24*AA24*AB24 -> 0 | AD24: 0 | AE24: 0 | AF24: 0 | AG24: =AD24*AE24*AF24 -> 0 | AH24: =AC24+AG24 -> 0 | AI24: =F24+G24+P24+Y24+AH24 -> 0 | AJ24: =AI24/E24 -> 0 | AK24: 2620.739 | AL24: 357.37 | AM24: 238.249 | AN24: 714.747 | AO24: 154.86185 | AP24: 0 | AQ24: =SUM(AL24:AP24) -> 1465.2278 | AR24: =AK24+AQ24 -> 4085.9668 | AS24: =E24-AR24 -> 19738.933
B25: 01/24 | C25: 160 | D25: DIRECIONAL_ ITAGUATINS_SAMAMBAIA | E25: 4018.49 | F25: 0 | G25: 0 | H25: 0 | I25: 0 | J25: 0 | K25: =H25*I25*J25 -> 0 | L25: 0 | M25: 0 | N25: 0 | O25: =L25*M25*N25 -> 0 | P25: =K25+O25 -> 0 | Q25: 0 | R25: 0 | S25: 0 | T25: =Q25*R25*S25 -> 0 | U25: 0 | V25: 0 | W25: 0 | X25: =U25*V25*W25 -> 0 | Y25: =T25+X25 -> 0 | Z25: 0 | AA25: 0 | AB25: 0 | AC25: =Z25*AA25*AB25 -> 0 | AD25: 0 | AE25: 0 | AF25: 0 | AG25: =AD25*AE25*AF25 -> 0 | AH25: =AC25+AG25 -> 0 | AI25: =F25+G25+P25+Y25+AH25 -> 0 | AJ25: =AI25/E25 -> 0 | AK25: 442.0339 | AL25: 60.28 | AM25: 40.1849 | AN25: 120.5547 | AO25: 26.120185 | AP25: 200.9245 | AQ25: =SUM(AL25:AP25) -> 448.06428 | AR25: =AK25+AQ25 -> 890.09818 | AS25: =E25-AR25 -> 3128.3918
B26: 01/24 | C26: 162 | D26: DIRECIONAL_TAGUATINGA_SANTA MARIA | E26: 3891.25 | F26: 0 | G26: 0 | H26: 0 | I26: 0 | J26: 0 | K26: =H26*I26*J26 -> 0 | L26: 0 | M26: 0 | N26: 0 | O26: =L26*M26*N26 -> 0 | P26: =K26+O26 -> 0 | Q26: 0 | R26: 0 | S26: 0 | T26: =Q26*R26*S26 -> 0 | U26: 0 | V26: 0 | W26: 0 | X26: =U26*V26*W26 -> 0 | Y26: =T26+X26 -> 0 | Z26: 0 | AA26: 0 | AB26: 0 | AC26: =Z26*AA26*AB26 -> 0 | AD26: 0 | AE26: 0 | AF26: 0 | AG26: =AD26*AE26*AF26 -> 0 | AH26: =AC26+AG26 -> 0 | AI26: =F26+G26+P26+Y26+AH26 -> 0 | AJ26: =AI26/E26 -> 0 | AK26: 428.0375 | AL26: 58.37 | AM26: 38.9125 | AN26: 116.7375 | AO26: 25.293125 | AP26: 0 | AQ26: =SUM(AL26:AP26) -> 239.31312 | AR26: =AK26+AQ26 -> 667.35063 | AS26: =E26-AR26 -> 3223.8994
B27: 01/24 | C27: 161 | D27: DIRECIONAL_ITAPEMA_PLANALTINA | E27: 4104.1 | F27: 0 | G27: 0 | H27: 0 | I27: 0 | J27: 0 | K27: =H27*I27*J27 -> 0 | L27: 0 | M27: 0 | N27: 0 | O27: =L27*M27*N27 -> 0 | P27: =K27+O27 -> 0 | Q27: 0 | R27: 0 | S27: 0 | T27: =Q27*R27*S27 -> 0 | U27: 0 | V27: 0 | W27: 0 | X27: =U27*V27*W27 -> 0 | Y27: =T27+X27 -> 0 | Z27: 0 | AA27: 0 | AB27: 0 | AC27: =Z27*AA27*AB27 -> 0 | AD27: 0 | AE27: 0 | AF27: 0 | AG27: =AD27*AE27*AF27 -> 0 | AH27: =AC27+AG27 -> 0 | AI27: =F27+G27+P27+Y27+AH27 -> 0 | AJ27: =AI27/E27 -> 0 | AK27: 451.451 | AL27: 61.56 | AM27: 41.041 | AN27: 123.123 | AO27: 26.67665 | AP27: 205.205 | AQ27: =SUM(AL27:AP27) -> 457.60565 | AR27: =AK27+AQ27 -> 909.05665 | AS27: =E27-AR27 -> 3195.0434
B28: 02/24 | C28: 185 | D28: AHSERC | E28: 5928 | F28: 950.61 | G28: 326.16667 | H28: 1 | I28: 16 | J28: 26 | K28: =H28*I28*J28 -> 416 | L28: 0 | M28: 0 | N28: 0 | O28: =L28*M28*N28 -> 0 | P28: =K28+O28 -> 416 | Q28: 1 | R28: 42.5 | S28: 26 | T28: =Q28*R28*S28 -> 1105 | U28: 0 | V28: 0 | W28: 0 | X28: =U28*V28*W28 -> 0 | Y28: =T28+X28 -> 1105 | Z28: 1 | AA28: 80 | AB28: 1 | AC28: =Z28*AA28*AB28 -> 80 | AD28: 0 | AE28: 0 | AF28: 0 | AG28: =AD28*AE28*AF28 -> 0 | AH28: =AC28+AG28 -> 80 | AI28: =F28+G28+P28+Y28+AH28 -> 2877.7767 | AJ28: =AI28/E28 -> 0.4854549 | AK28: 335.52457 | AL28: 59.28 | AM28: 59.28 | AN28: 177.84 | AO28: 38.532 | AP28: 296.4 | AQ28: =SUM(AL28:AP28) -> 631.332 | AR28: =AK28+AQ28 -> 966.85657 | AS28: =E28-AR28 -> 4961.1434
B29: 02/24 | C29: 171 | D29: RIO PARANÃ | E29: 16252 | F29: 2331.4 | G29: 300 | H29: 1 | I29: 16 | J29: 26 | K29: =H29*I29*J29 -> 416 | L29: 2 | M29: 16 | N29: 16 | O29: =L29*M29*N29 -> 512 | P29: =K29+O29 -> 928 | Q29: 1 | R29: 42.5 | S29: 26 | T29: =Q29*R29*S29 -> 1105 | U29: 2 | V29: 42.5 | W29: 16 | X29: =U29*V29*W29 -> 1360 | Y29: =T29+X29 -> 2465 | Z29: 1 | AA29: 80 | AB29: 1 | AC29: =Z29*AA29*AB29 -> 80 | AD29: 2 | AE29: 80 | AF29: 1 | AG29: =AD29*AE29*AF29 -> 160 | AH29: =AC29+AG29 -> 240 | AI29: =F29+G29+P29+Y29+AH29 -> 6264.4 | AJ29: =AI29/E29 -> 0.3854541 | AK29: 1098.636 | AL29: 162.52 | AM29: 162.52 | AN29: 487.56 | AO29: 105.638 | AP29: 812.6 | AQ29: =SUM(AL29:AP29) -> 1730.838 | AR29: =AK29+AQ29 -> 2829.474 | AS29: =E29-AR29 -> 13422.526
B30: 02/24 | C30: 165 | D30: VANESSA | E30: 5562 | F30: 911.65 | G30: 187.41667 | H30: 1 | I30: 16 | J30: 26 | K30: =H30*I30*J30 -> 416 | L30: 0 | M30: 0 | N30: 0 | O30: =L30*M30*N30 -> 0 | P30: =K30+O30 -> 416 | Q30: 1 | R30: 42.5 | S30: 26 | T30: =Q30*R30*S30 -> 1105 | U30: 0 | V30: 0 | W30: 0 | X30: =U30*V30*W30 -> 0 | Y30: =T30+X30 -> 1105 | Z30: 1 | AA30: 80 | AB30: 1 | AC30: =Z30*AA30*AB30 -> 80 | AD30: 0 | AE30: 0 | AF30: 0 | AG30: =AD30*AE30*AF30 -> 0 | AH30: =AC30+AG30 -> 80 | AI30: =F30+G30+P30+Y30+AH30 -> 2700.0667 | AJ30: =AI30/E30 -> 0.48544888 | AK30: 314.81267 | AL30: 55.62 | AM30: 55.62 | AN30: 166.86 | AO30: 36.153 | AP30: 278.1 | AQ30: =SUM(AL30:AP30) -> 592.353 | AR30: =AK30+AQ30 -> 907.16567 | AS30: =E30-AR30 -> 4654.8343
B31: 02/24 | C31: 166 | D31: ATLANTIS | E31: 26266 | F31: 3822 | G31: 0 | H31: 3 | I31: 16 | J31: 26 | K31: =H31*I31*J31 -> 1248 | L31: 2 | M31: 16 | N31: =16+4 -> 20 | O31: =L31*M31*N31 -> 640 | P31: =K31+O31 -> 1888 | Q31: 3 | R31: 42.5 | S31: 26 | T31: =Q31*R31*S31 -> 3315 | U31: 2 | V31: 42.5 | W31: =16+4 -> 20 | X31: =U31*V31*W31 -> 1700 | Y31: =T31+X31 -> 5015 | Z31: 3 | AA31: 60 | AB31: 1 | AC31: =Z31*AA31*AB31 -> 180 | AD31: 3 | AE31: 90 | AF31: 1 | AG31: =AD31*AE31*AF31 -> 270 | AH31: =AC31+AG31 -> 450 | AI31: =F31+G31+P31+Y31+AH31 -> 11175 | AJ31: =AI31/E31 -> 0.42545496 | AK31: 1660.01 | AL31: 262.66 | AM31: 262.66 | AN31: 787.98 | AO31: 170.729 | AP31: 1313.3 | AQ31: =SUM(AL31:AP31) -> 2797.329 | AR31: =AK31+AQ31 -> 4457.339 | AS31: =E31-AR31 -> 21808.661
B32: 02/24 | C32: 168 | D32: QUATRO ESTAÇÕES 509 | E32: 5810 | F32: 710.95 | G32: 350 | H32: 1 | I32: 16 | J32: 26 | K32: =H32*I32*J32 -> 416 | L32: 0 | M32: 0 | N32: 0 | O32: =L32*M32*N32 -> 0 | P32: =K32+O32 -> 416 | Q32: 1 | R32: 42.5 | S32: 26 | T32: =Q32*R32*S32 -> 1105 | U32: 0 | V32: 0 | W32: 0 | X32: =U32*V32*W32 -> 0 | Y32: =T32+X32 -> 1105 | Z32: 1 | AA32: 80 | AB32: 1 | AC32: =Z32*AA32*AB32 -> 80 | AD32: 0 | AE32: 0 | AF32: 0 | AG32: =AD32*AE32*AF32 -> 0 | AH32: =AC32+AG32 -> 80 | AI32: =F32+G32+P32+Y32+AH32 -> 2661.95 | AJ32: =AI32/E32 -> 0.45816695 | AK32: 346.2855 | AL32: 58.1 | AM32: 58.1 | AN32: 174.3 | AO32: 37.765 | AP32: 290.5 | AQ32: =SUM(AL32:AP32) -> 618.765 | AR32: =AK32+AQ32 -> 965.0505 | AS32: =E32-AR32 -> 4844.9495
B33: 02/24 | C33: 169 | D33: QUATRO ESTAÇÕES 507 | E33: 5928 | F33: 898.55 | G33: 216.5 | H33: 1 | I33: 16 | J33: 26 | K33: =H33*I33*J33 -> 416 | L33: 0 | M33: 0 | N33: 0 | O33: =L33*M33*N33 -> 0 | P33: =K33+O33 -> 416 | Q33: 1 | R33: 42.5 | S33: 26 | T33: =Q33*R33*S33 -> 1105 | U33: 0 | V33: 0 | W33: 0 | X33: =U33*V33*W33 -> 0 | Y33: =T33+X33 -> 1105 | Z33: 1 | AA33: 80 | AB33: 1 | AC33: =Z33*AA33*AB33 -> 80 | AD33: 0 | AE33: 0 | AF33: 0 | AG33: =AD33*AE33*AF33 -> 0 | AH33: =AC33+AG33 -> 80 | AI33: =F33+G33+P33+Y33+AH33 -> 2716.05 | AJ33: =AI33/E33 -> 0.45817308 | AK33: 353.3145 | AL33: 59.28 | AM33: 59.28 | AN33: 177.84 | AO33: 38.532 | AP33: 296.4 | AQ33: =SUM(AL33:AP33) -> 631.332 | AR33: =AK33+AQ33 -> 984.6465 | AS33: =E33-AR33 -> 4943.3535
B34: 02/24 | C34: 170 | D34: TAJ MAHAL | E34: 36840 | F34: 2809.7 | G34: 0 | H34: 1 | I34: 16 | J34: 26 | K34: =H34*I34*J34 -> 416 | L34: 2 | M34: 24 | N34: 16 | O34: =L34*M34*N34 -> 768 | P34: =K34+O34 -> 1184 | Q34: 4 | R34: 20 | S34: 22 | T34: =Q34*R34*S34 -> 1760 | U34: 2 | V34: 20 | W34: 15.5 | X34: =U34*V34*W34 -> 620 | Y34: =T34+X34 -> 2380 | Z34: 4 | AA34: =90/12 -> 7.5 | AB34: 2 | AC34: =Z34*AA34*AB34 -> 60 | AD34: 2 | AE34: =90/12 -> 7.5 | AF34: 2 | AG34: =AD34*AE34*AF34 -> 30 | AH34: =AC34+AG34 -> 90 | AI34: =F34+G34+P34+Y34+AH34 -> 6463.7 | AJ34: =AI34/E34 -> 0.17545331 | AK34: 3341.393 | AL34: 368.4 | AM34: 368.4 | AN34: 1105.2 | AO34: 239.46 | AP34: 0 | AQ34: =SUM(AL34:AP34) -> 2081.46 | AR34: =AK34+AQ34 -> 5422.853 | AS34: =E34-AR34 -> 31417.147
B35: 02/24 | C35: 172 | D35: AHSERC | E35: 470 | F35: 228.16 | G35: 0 | H35: 0 | I35: 0 | J35: 0 | K35: =H35*I35*J35 -> 0 | L35: 0 | M35: 0 | N35: 0 | O35: =L35*M35*N35 -> 0 | P35: =K35+O35 -> 0 | Q35: 0 | R35: 0 | S35: 0 | T35: =Q35*R35*S35 -> 0 | U35: 0 | V35: 0 | W35: 0 | X35: =U35*V35*W35 -> 0 | Y35: =T35+X35 -> 0 | Z35: 0 | AA35: 0 | AB35: 0 | AC35: =Z35*AA35*AB35 -> 0 | AD35: 0 | AE35: 0 | AF35: 0 | AG35: =AD35*AE35*AF35 -> 0 | AH35: =AC35+AG35 -> 0 | AI35: =F35+G35+P35+Y35+AH35 -> 228.16 | AJ35: =AI35/E35 -> 0.48544681 | AK35: 26.6024 | AL35: 4.7 | AM35: 4.7 | AN35: 14.1 | AO35: 3.055 | AP35: 23.5 | AQ35: =SUM(AL35:AP35) -> 50.055 | AR35: =AK35+AQ35 -> 76.6574 | AS35: =E35-AR35 -> 393.3426
B36: 02/24 | C36: 177 | D36: RIO PARANÃ | E36: 1456 | F36: 561.22 | G36: 0 | H36: 0 | I36: 0 | J36: 0 | K36: =H36*I36*J36 -> 0 | L36: 0 | M36: 0 | N36: 0 | O36: =L36*M36*N36 -> 0 | P36: =K36+O36 -> 0 | Q36: 0 | R36: 0 | S36: 0 | T36: =Q36*R36*S36 -> 0 | U36: 0 | V36: 42.5 | W36: 0 | X36: =U36*V36*W36 -> 0 | Y36: =T36+X36 -> 0 | Z36: 0 | AA36: 0 | AB36: 0 | AC36: =Z36*AA36*AB36 -> 0 | AD36: 0 | AE36: 0 | AF36: 0 | AG36: =AD36*AE36*AF36 -> 0 | AH36: =AC36+AG36 -> 0 | AI36: =F36+G36+P36+Y36+AH36 -> 561.22 | AJ36: =AI36/E36 -> 0.3854533 | AK36: 98.4258 | AL36: 14.56 | AM36: 14.56 | AN36: 43.68 | AO36: 9.464 | AP36: 72.8 | AQ36: =SUM(AL36:AP36) -> 155.064 | AR36: =AK36+AQ36 -> 253.4898 | AS36: =E36-AR36 -> 1202.5102
B37: 02/24 | C37: 179 | D37: VANESSA | E37: 762 | F37: 369.91 | G37: 0 | H37: 0 | I37: 0 | J37: 0 | K37: =H37*I37*J37 -> 0 | L37: 0 | M37: 0 | N37: 0 | O37: =L37*M37*N37 -> 0 | P37: =K37+O37 -> 0 | Q37: 0 | R37: 0 | S37: 0 | T37: =Q37*R37*S37 -> 0 | U37: 0 | V37: 0 | W37: 0 | X37: =U37*V37*W37 -> 0 | Y37: =T37+X37 -> 0 | Z37: 0 | AA37: 0 | AB37: 0 | AC37: =Z37*AA37*AB37 -> 0 | AD37: 0 | AE37: 0 | AF37: 0 | AG37: =AD37*AE37*AF37 -> 0 | AH37: =AC37+AG37 -> 0 | AI37: =F37+G37+P37+Y37+AH37 -> 369.91 | AJ37: =AI37/E37 -> 0.48544619 | AK37: 43.1299 | AL37: 7.62 | AM37: 7.62 | AN37: 22.86 | AO37: 4.953 | AP37: 38.1 | AQ37: =SUM(AL37:AP37) -> 81.153 | AR37: =AK37+AQ37 -> 124.2829 | AS37: =E37-AR37 -> 637.7171
B38: 02/24 | C38: 173 | D38: ATLANTIS | E38: 1966 | F38: 836.44 | G38: 0 | H38: 0 | I38: 0 | J38: 0 | K38: =H38*I38*J38 -> 0 | L38: 0 | M38: 0 | N38: 0 | O38: =L38*M38*N38 -> 0 | P38: =K38+O38 -> 0 | Q38: 0 | R38: 0 | S38: 0 | T38: =Q38*R38*S38 -> 0 | U38: 0 | V38: 0 | W38: 0 | X38: =U38*V38*W38 -> 0 | Y38: =T38+X38 -> 0 | Z38: 0 | AA38: 0 | AB38: 0 | AC38: =Z38*AA38*AB38 -> 0 | AD38: 0 | AE38: 0 | AF38: 0 | AG38: =AD38*AE38*AF38 -> 0 | AH38: =AC38+AG38 -> 0 | AI38: =F38+G38+P38+Y38+AH38 -> 836.44 | AJ38: =AI38/E38 -> 0.4254527 | AK38: 124.2516 | AL38: 19.66 | AM38: 19.66 | AN38: 58.98 | AO38: 12.779 | AP38: 98.3 | AQ38: =SUM(AL38:AP38) -> 209.379 | AR38: =AK38+AQ38 -> 333.6306 | AS38: =E38-AR38 -> 1632.3694
B39: 02/24 | C39: 175 | D39: QUATRO ESTAÇÕES 509 | E39: 611 | F39: 279.94 | G39: 0 | H39: 0 | I39: 0 | J39: 0 | K39: =H39*I39*J39 -> 0 | L39: 0 | M39: 0 | N39: 0 | O39: =L39*M39*N39 -> 0 | P39: =K39+O39 -> 0 | Q39: 0 | R39: 0 | S39: 0 | T39: =Q39*R39*S39 -> 0 | U39: 0 | V39: 0 | W39: 0 | X39: =U39*V39*W39 -> 0 | Y39: =T39+X39 -> 0 | Z39: 0 | AA39: 0 | AB39: 0 | AC39: =Z39*AA39*AB39 -> 0 | AD39: 0 | AE39: 0 | AF39: 0 | AG39: =AD39*AE39*AF39 -> 0 | AH39: =AC39+AG39 -> 0 | AI39: =F39+G39+P39+Y39+AH39 -> 279.94 | AJ39: =AI39/E39 -> 0.45816694 | AK39: 36.4166 | AL39: 6.11 | AM39: 6.11 | AN39: 18.33 | AO39: 3.9715 | AP39: 30.55 | AQ39: =SUM(AL39:AP39) -> 65.0715 | AR39: =AK39+AQ39 -> 101.4881 | AS39: =E39-AR39 -> 509.5119
B40: 02/24 | C40: 174 | D40: QUATRO ESTAÇÕES 507 | E40: 551 | F40: 252.45 | G40: 0 | H40: 0 | I40: 0 | J40: 0 | K40: =H40*I40*J40 -> 0 | L40: 0 | M40: 0 | N40: 0 | O40: =L40*M40*N40 -> 0 | P40: =K40+O40 -> 0 | Q40: 0 | R40: 0 | S40: 0 | T40: =Q40*R40*S40 -> 0 | U40: 0 | V40: 0 | W40: 0 | X40: =U40*V40*W40 -> 0 | Y40: =T40+X40 -> 0 | Z40: 0 | AA40: 0 | AB40: 0 | AC40: =Z40*AA40*AB40 -> 0 | AD40: 0 | AE40: 0 | AF40: 0 | AG40: =AD40*AE40*AF40 -> 0 | AH40: =AC40+AG40 -> 0 | AI40: =F40+G40+P40+Y40+AH40 -> 252.45 | AJ40: =AI40/E40 -> 0.45816697 | AK40: 32.8405 | AL40: 5.51 | AM40: 5.51 | AN40: 16.53 | AO40: 3.5815 | AP40: 27.55 | AQ40: =SUM(AL40:AP40) -> 58.6815 | AR40: =AK40+AQ40 -> 91.522 | AS40: =E40-AR40 -> 459.478
B41: 02/24 | C41: 178 | D41: TAJ MAHAL | E41: 3053.58 | F41: 535.76 | G41: 0 | H41: 0 | I41: 0 | J41: 0 | K41: =H41*I41*J41 -> 0 | L41: 0 | M41: 0 | N41: 0 | O41: =L41*M41*N41 -> 0 | P41: =K41+O41 -> 0 | Q41: 0 | R41: 0 | S41: 0 | T41: =Q41*R41*S41 -> 0 | U41: 0 | V41: 0 | W41: 0 | X41: =U41*V41*W41 -> 0 | Y41: =T41+X41 -> 0 | Z41: 0 | AA41: 0 | AB41: 0 | AC41: =Z41*AA41*AB41 -> 0 | AD41: 0 | AE41: 0 | AF41: 0 | AG41: =AD41*AE41*AF41 -> 0 | AH41: =AC41+AG41 -> 0 | AI41: =F41+G41+P41+Y41+AH41 -> 535.76 | AJ41: =AI41/E41 -> 0.17545307 | AK41: 276.9602 | AL41: 30.5358 | AM41: 30.5358 | AN41: 91.6074 | AO41: 19.84827 | AP41: 0 | AQ41: =SUM(AL41:AP41) -> 172.52727 | AR41: =AK41+AQ41 -> 449.48747 | AS41: =E41-AR41 -> 2604.0925
B42: 02/24 | C42: 181 | D42: DIRECIONAL_ ÁGUA BRANCA_SOBRADINHO | E42: 23325.27 | F42: 0 | G42: 0 | H42: 0 | I42: 0 | J42: 0 | K42: =H42*I42*J42 -> 0 | L42: 0 | M42: 0 | N42: 0 | O42: =L42*M42*N42 -> 0 | P42: =K42+O42 -> 0 | Q42: 0 | R42: 0 | S42: 0 | T42: =Q42*R42*S42 -> 0 | U42: 0 | V42: 0 | W42: 0 | X42: =U42*V42*W42 -> 0 | Y42: =T42+X42 -> 0 | Z42: 0 | AA42: 0 | AB42: 0 | AC42: =Z42*AA42*AB42 -> 0 | AD42: 0 | AE42: 0 | AF42: 0 | AG42: =AD42*AE42*AF42 -> 0 | AH42: =AC42+AG42 -> 0 | AI42: =F42+G42+P42+Y42+AH42 -> 0 | AJ42: =AI42/E42 -> 0 | AK42: 2565.7797 | AL42: 233.2527 | AM42: 233.2527 | AN42: 699.7581 | AO42: 151.61425 | AP42: 0 | AQ42: =SUM(AL42:AP42) -> 1317.8778 | AR42: =AK42+AQ42 -> 3883.6575 | AS42: =E42-AR42 -> 19441.613
B43: 02/24 | C43: 182 | D43: DIRECIONAL_ ITAGUATINS_SAMAMBAIA | E43: 4018.49 | F43: 0 | G43: 0 | H43: 0 | I43: 0 | J43: 0 | K43: =H43*I43*J43 -> 0 | L43: 0 | M43: 0 | N43: 0 | O43: =L43*M43*N43 -> 0 | P43: =K43+O43 -> 0 | Q43: 0 | R43: 0 | S43: 0 | T43: =Q43*R43*S43 -> 0 | U43: 0 | V43: 0 | W43: 0 | X43: =U43*V43*W43 -> 0 | Y43: =T43+X43 -> 0 | Z43: 0 | AA43: 0 | AB43: 0 | AC43: =Z43*AA43*AB43 -> 0 | AD43: 0 | AE43: 0 | AF43: 0 | AG43: =AD43*AE43*AF43 -> 0 | AH43: =AC43+AG43 -> 0 | AI43: =F43+G43+P43+Y43+AH43 -> 0 | AJ43: =AI43/E43 -> 0 | AK43: 442.0339 | AL43: 40.1849 | AM43: 40.1849 | AN43: 120.5547 | AO43: 26.120185 | AP43: 200.9245 | AQ43: =SUM(AL43:AP43) -> 427.96918 | AR43: =AK43+AQ43 -> 870.00308 | AS43: =E43-AR43 -> 3148.4869
B44: 02/24 | C44: 184 | D44: DIRECIONAL_TAGUATINGA_SANTA MARIA | E44: 3891.25 | F44: 0 | G44: 0 | H44: 0 | I44: 0 | J44: 0 | K44: =H44*I44*J44 -> 0 | L44: 0 | M44: 0 | N44: 0 | O44: =L44*M44*N44 -> 0 | P44: =K44+O44 -> 0 | Q44: 0 | R44: 0 | S44: 0 | T44: =Q44*R44*S44 -> 0 | U44: 0 | V44: 0 | W44: 0 | X44: =U44*V44*W44 -> 0 | Y44: =T44+X44 -> 0 | Z44: 0 | AA44: 0 | AB44: 0 | AC44: =Z44*AA44*AB44 -> 0 | AD44: 0 | AE44: 0 | AF44: 0 | AG44: =AD44*AE44*AF44 -> 0 | AH44: =AC44+AG44 -> 0 | AI44: =F44+G44+P44+Y44+AH44 -> 0 | AJ44: =AI44/E44 -> 0 | AK44: 428.0375 | AL44: 38.9125 | AM44: 38.9125 | AN44: 116.7375 | AO44: 25.293125 | AP44: 0 | AQ44: =SUM(AL44:AP44) -> 219.85563 | AR44: =AK44+AQ44 -> 647.89313 | AS44: =E44-AR44 -> 3243.3569
...

Sheet 2026_RECEITA _JJB SERV
B1: JJ BARBOSA SERVIÇOS
B2: RECEITA
B4: CNAE-Fiscal: | D4: N812140000 _ LIMPEZA EM PREDIOS E EM DOMICILIOS
B5: ATIVIDADE MUNICIPIO: | D5: 710 - 7.10 - Limpeza, manutenção e conservação de vias e logradouros
B7: ANO: | C7: 2026 | D7: VERSÃO 2024.11.20
B8: CLIENTE: | C8: JJ BARBOSA SERVIÇOS | E8: REGIME DE TRIBUTAÇÃO: | F8: SIMPLES NACIONAL
B9: CNPJ: | C9: 27.468,199.0001-33
B10: ENDEREÇO: | C10: ÁGUAS CLARAS
B11: TOTAL | C11: =E179 -> 108198
B13: COMP | C13: NF | D13: CLIENTE | E13: VALOR TOTAL DOS SERVIÇOS | F13: MATERIAS | G13: EQUIPAMENTOS | H13: VALE TRANSPORTE | Q13: VALE ALIMENTAÇÃO | Z13: UNIFORME | AI13: TOTAL BASE RETENÇÃO INSS | AJ13: BASE CÁCULO INSS | AK13: RETENÇÃO DESTACADO NA NF | AS13: TOTAL RETENÇÃO NF | AT13: VALOR LIQUIDO DA NOTA FISCAL
H14: 44H/S | L14: 12 X 36 | P14: TOTAL | Q14: 44H/S | U14: 12 X 36 | Y14: TOTAL | Z14: 44H/S | AD14: 12 X 36 | AH14: TOTAL | AK14: GPS 2631 | AL14: IRRJ 1001 | AM14: CSLL 1002 | AN14: COFINS 1004 | AO14: PIS 1005 | AP14: ISSQN 1732 | AR14: TOTAL
H15: QTDE | I15: $ UNIT | J15: DIAS | K15: TOTAL | L15: QTDE | M15: $ UNIT | N15: DIAS | O15: TOTAL | Q15: QTDE | R15: $ UNIT | S15: DIAS | T15: TOTAL | U15: QTDE | V15: $ UNIT | W15: DIAS | X15: TOTAL | Z15: QTDE | AA15: $ UNIT | AB15: ANO | AC15: TOTAL | AD15: QTDE | AE15: $ UNIT | AF15: ANO | AG15: TOTAL | AJ15: % | AK15: 0.11 | AL15: 0 | AM15: 0 | AN15: 0 | AO15: 0 | AP15: % | AQ15: $ | AR15: =SUBTOTAL(9,AL15:AQ15) -> 0 | AS15: =AK15+AR15 -> 0.11
AR16: =AL16+AM16+AN16+AO16+AQ16 -> 0
B17: 01/24 | C17: 050_GRENWAY | D17: PAINEIRA | E17: 27970 | F17: 4247 | G17: 2550 | H17: 2 | I17: 24 | J17: 26 | K17: =H17*I17*J17 -> 1248 | L17: 4 | M17: 16 | N17: 16 | O17: =L17*M17*N17 -> 1024 | P17: =K17+O17 -> 2272 | Q17: 2 | R17: 42.5 | S17: 26 | T17: =Q17*R17*S17 -> 2210 | U17: 4 | V17: 42.5 | W17: 16 | X17: =U17*V17*W17 -> 2720 | Y17: =T17+X17 -> 4930 | Z17: 2 | AA17: 80 | AB17: 1 | AC17: =Z17*AA17*AB17 -> 160 | AD17: 4 | AE17: 90 | AF17: 1 | AG17: =AD17*AE17*AF17 -> 360 | AH17: =AC17+AG17 -> 520 | AI17: =F17+G17+P17+Y17+AH17 -> 14519 | AJ17: =AI17/E17 -> 0.51909188 | AK17: =(E17-AI17)*$AK$15 -> 1479.61 | AL17: 0 | AM17: 0 | AN17: 0 | AO17: 0 | AP17: 0.05 | AQ17: =AP17*E17 -> 1398.5 | AR17: =AL17+AM17+AN17+AO17+AQ17 -> 1398.5 | AS17: =AK17+AR17 -> 2878.11 | AT17: =E17-AS17 -> 25091.89
B18: 01/24 | C18: 051_GRENWAY | D18: SUMMER | E18: 28630 | F18: 4563.5 | G18: 2550 | H18: 2 | I18: 24 | J18: 26 | K18: =H18*I18*J18 -> 1248 | L18: 4 | M18: 16 | N18: 16 | O18: =L18*M18*N18 -> 1024 | P18: =K18+O18 -> 2272 | Q18: 2 | R18: 42.5 | S18: 26 | T18: =Q18*R18*S18 -> 2210 | U18: 4 | V18: 42.5 | W18: 16 | X18: =U18*V18*W18 -> 2720 | Y18: =T18+X18 -> 4930 | Z18: 2 | AA18: 80 | AB18: 1 | AC18: =Z18*AA18*AB18 -> 160 | AD18: 4 | AE18: 90 | AF18: 1 | AG18: =AD18*AE18*AF18 -> 360 | AH18: =AC18+AG18 -> 520 | AI18: =F18+G18+P18+Y18+AH18 -> 14835.5 | AJ18: =AI18/E18 -> 0.51818023 | AK18: =(E18-AI18)*$AK$15 -> 1517.395 | AL18: 0 | AM18: 0 | AN18: 0 | AO18: 0 | AP18: 0.05 | AQ18: =AP18*E18 -> 1431.5 | AR18: =AL18+AM18+AN18+AO18+AQ18 -> 1431.5 | AS18: =AK18+AR18 -> 2948.895 | AT18: =E18-AS18 -> 25681.105
B19: 02/24 | C19: 052 | D19: PAINEIRA | E19: 29976 | F19: 5288.3 | G19: 2550 | H19: 2 | I19: 24 | J19: 26 | K19: =H19*I19*J19 -> 1248 | L19: 4 | M19: 16 | N19: 16 | O19: =L19*M19*N19 -> 1024 | P19: =K19+O19 -> 2272 | Q19: 2 | R19: 42.5 | S19: 26 | T19: =Q19*R19*S19 -> 2210 | U19: 4 | V19: 42.5 | W19: 16 | X19: =U19*V19*W19 -> 2720 | Y19: =T19+X19 -> 4930 | Z19: 2 | AA19: 80 | AB19: 1 | AC19: =Z19*AA19*AB19 -> 160 | AD19: 4 | AE19: 90 | AF19: 1 | AG19: =AD19*AE19*AF19 -> 360 | AH19: =AC19+AG19 -> 520 | AI19: =F19+G19+P19+Y19+AH19 -> 15560.3 | AJ19: =AI19/E19 -> 0.51909194 | AK19: =(E19-AI19)*$AK$15 -> 1585.727 | AL19: 0 | AM19: 0 | AN19: 0 | AO19: 0 | AP19: 0.05 | AQ19: =AP19*E19 -> 1498.8 | AR19: =AL19+AM19+AN19+AO19+AQ19 -> 1498.8 | AS19: =AK19+AR19 -> 3084.527 | AT19: =E19-AS19 -> 26891.473
B20: 02/24 | C20: 053 | D20: SUMMER | E20: 30680 | F20: 5625.8 | G20: 2550 | H20: 2 | I20: 24 | J20: 26 | K20: =H20*I20*J20 -> 1248 | L20: 4 | M20: 16 | N20: 16 | O20: =L20*M20*N20 -> 1024 | P20: =K20+O20 -> 2272 | Q20: 2 | R20: 42.5 | S20: 26 | T20: =Q20*R20*S20 -> 2210 | U20: 4 | V20: 42.5 | W20: 16 | X20: =U20*V20*W20 -> 2720 | Y20: =T20+X20 -> 4930 | Z20: 2 | AA20: 80 | AB20: 1 | AC20: =Z20*AA20*AB20 -> 160 | AD20: 4 | AE20: 90 | AF20: 1 | AG20: =AD20*AE20*AF20 -> 360 | AH20: =AC20+AG20 -> 520 | AI20: =F20+G20+P20+Y20+AH20 -> 15897.8 | AJ20: =AI20/E20 -> 0.51818123 | AK20: =(E20-AI20)*$AK$15 -> 1626.042 | AL20: 0 | AM20: 0 | AN20: 0 | AO20: 0 | AP20: 0.05 | AQ20: =AP20*E20 -> 1534 | AR20: =AL20+AM20+AN20+AO20+AQ20 -> 1534 | AS20: =AK20+AR20 -> 3160.042 | AT20: =E20-AS20 -> 27519.958
B21: 02/24 | C21: 054 | D21: PAINEIRA | E21: 2006 | F21: 1041.3 | G21: 0 | H21: 0 | I21: 0 | J21: 0 | K21: =H21*I21*J21 -> 0 | L21: 0 | M21: 0 | N21: 0 | O21: =L21*M21*N21 -> 0 | P21: =K21+O21 -> 0 | Q21: 0 | R21: 0 | S21: 0 | T21: =Q21*R21*S21 -> 0 | U21: 0 | V21: 0 | W21: 0 | X21: =U21*V21*W21 -> 0 | Y21: =T21+X21 -> 0 | Z21: 0 | AA21: 0 | AB21: 0 | AC21: =Z21*AA21*AB21 -> 0 | AD21: 0 | AE21: 0 | AF21: 0 | AG21: =AD21*AE21*AF21 -> 0 | AH21: =AC21+AG21 -> 0 | AI21: =F21+G21+P21+Y21+AH21 -> 1041.3 | AJ21: =AI21/E21 -> 0.51909272 | AK21: =(E21-AI21)*$AK$15 -> 106.117 | AL21: 0 | AM21: 0 | AN21: 0 | AO21: 0 | AP21: 0.05 | AQ21: =AP21*E21 -> 100.3 | AR21: =AL21+AM21+AN21+AO21+AQ21 -> 100.3 | AS21: =AK21+AR21 -> 206.417 | AT21: =E21-AS21 -> 1799.583
B22: 02/24 | C22: 055 | D22: SUMMER | E22: 2050 | F22: 1062.3 | G22: 0 | H22: 0 | I22: 0 | J22: 0 | K22: =H22*I22*J22 -> 0 | L22: 0 | M22: 0 | N22: 0 | O22: =L22*M22*N22 -> 0 | P22: =K22+O22 -> 0 | Q22: 0 | R22: 0 | S22: 0 | T22: =Q22*R22*S22 -> 0 | U22: 0 | V22: 0 | W22: 0 | X22: =U22*V22*W22 -> 0 | Y22: =T22+X22 -> 0 | Z22: 0 | AA22: 0 | AB22: 0 | AC22: =Z22*AA22*AB22 -> 0 | AD22: 0 | AE22: 0 | AF22: 0 | AG22: =AD22*AE22*AF22 -> 0 | AH22: =AC22+AG22 -> 0 | AI22: =F22+G22+P22+Y22+AH22 -> 1062.3 | AJ22: =AI22/E22 -> 0.51819512 | AK22: =(E22-AI22)*$AK$15 -> 108.647 | AL22: 0 | AM22: 0 | AN22: 0 | AO22: 0 | AP22: 0.05 | AQ22: =AP22*E22 -> 102.5 | AR22: =AL22+AM22+AN22+AO22+AQ22 -> 102.5 | AS22: =AK22+AR22 -> 211.147 | AT22: =E22-AS22 -> 1838.853
B23: 03/24 | C23: 056 | D23: PAINEIRA | E23: 29976 | F23: 5288.3 | G23: 2550 | H23: 2 | I23: 24 | J23: 26 | K23: =H23*I23*J23 -> 1248 | L23: 4 | M23: 16 | N23: 16 | O23: =L23*M23*N23 -> 1024 | P23: =K23+O23 -> 2272 | Q23: 2 | R23: 42.5 | S23: 26 | T23: =Q23*R23*S23 -> 2210 | U23: 4 | V23: 42.5 | W23: 16 | X23: =U23*V23*W23 -> 2720 | Y23: =T23+X23 -> 4930 | Z23: 2 | AA23: 80 | AB23: 1 | AC23: =Z23*AA23*AB23 -> 160 | AD23: 4 | AE23: 90 | AF23: 1 | AG23: =AD23*AE23*AF23 -> 360 | AH23: =AC23+AG23 -> 520 | AI23: =F23+G23+P23+Y23+AH23 -> 15560.3 | AJ23: =AI23/E23 -> 0.51909194 | AK23: =(E23-AI23)*$AK$15 -> 1585.727 | AL23: 0 | AM23: 0 | AN23: 0 | AO23: 0 | AP23: 0.05 | AQ23: =AP23*E23 -> 1498.8 | AR23: =AL23+AM23+AN23+AO23+AQ23 -> 1498.8 | AS23: =AK23+AR23 -> 3084.527 | AT23: =E23-AS23 -> 26891.473
B24: 03/24 | C24: 057 | D24: SUMMER | E24: 30680 | F24: 5625.8 | G24: 2550 | H24: 2 | I24: 24 | J24: 26 | K24: =H24*I24*J24 -> 1248 | L24: 4 | M24: 16 | N24: 16 | O24: =L24*M24*N24 -> 1024 | P24: =K24+O24 -> 2272 | Q24: 2 | R24: 42.5 | S24: 26 | T24: =Q24*R24*S24 -> 2210 | U24: 4 | V24: 42.5 | W24: 16 | X24: =U24*V24*W24 -> 2720 | Y24: =T24+X24 -> 4930 | Z24: 2 | AA24: 80 | AB24: 1 | AC24: =Z24*AA24*AB24 -> 160 | AD24: 4 | AE24: 90 | AF24: 1 | AG24: =AD24*AE24*AF24 -> 360 | AH24: =AC24+AG24 -> 520 | AI24: =F24+G24+P24+Y24+AH24 -> 15897.8 | AJ24: =AI24/E24 -> 0.51818123 | AK24: =(E24-AI24)*$AK$15 -> 1626.042 | AL24: 0 | AM24: 0 | AN24: 0 | AO24: 0 | AP24: 0.05 | AQ24: =AP24*E24 -> 1534 | AR24: =AL24+AM24+AN24+AO24+AQ24 -> 1534 | AS24: =AK24+AR24 -> 3160.042 | AT24: =E24-AS24 -> 27519.958
B25: 04/24 | C25: 058 | D25: PAINEIRA | E25: 29976 | F25: 5288.3 | G25: 2550 | H25: 2 | I25: 24 | J25: 26 | K25: =H25*I25*J25 -> 1248 | L25: 4 | M25: 16 | N25: 16 | O25: =L25*M25*N25 -> 1024 | P25: =K25+O25 -> 2272 | Q25: 2 | R25: 42.5 | S25: 26 | T25: =Q25*R25*S25 -> 2210 | U25: 4 | V25: 42.5 | W25: 16 | X25: =U25*V25*W25 -> 2720 | Y25: =T25+X25 -> 4930 | Z25: 2 | AA25: 80 | AB25: 1 | AC25: =Z25*AA25*AB25 -> 160 | AD25: 4 | AE25: 90 | AF25: 1 | AG25: =AD25*AE25*AF25 -> 360 | AH25: =AC25+AG25 -> 520 | AI25: =F25+G25+P25+Y25+AH25 -> 15560.3 | AJ25: =AI25/E25 -> 0.51909194 | AK25: =(E25-AI25)*$AK$15 -> 1585.727 | AL25: 0 | AM25: 0 | AN25: 0 | AO25: 0 | AP25: 0.05 | AQ25: =AP25*E25 -> 1498.8 | AR25: =AL25+AM25+AN25+AO25+AQ25 -> 1498.8 | AS25: =AK25+AR25 -> 3084.527 | AT25: =E25-AS25 -> 26891.473
B26: 04/24 | C26: 059 | D26: SUMMER | E26: 30680 | F26: 5625.8 | G26: 2550 | H26: 2 | I26: 24 | J26: 26 | K26: =H26*I26*J26 -> 1248 | L26: 4 | M26: 16 | N26: 16 | O26: =L26*M26*N26 -> 1024 | P26: =K26+O26 -> 2272 | Q26: 2 | R26: 42.5 | S26: 26 | T26: =Q26*R26*S26 -> 2210 | U26: 4 | V26: 42.5 | W26: 16 | X26: =U26*V26*W26 -> 2720 | Y26: =T26+X26 -> 4930 | Z26: 2 | AA26: 80 | AB26: 1 | AC26: =Z26*AA26*AB26 -> 160 | AD26: 4 | AE26: 90 | AF26: 1 | AG26: =AD26*AE26*AF26 -> 360 | AH26: =AC26+AG26 -> 520 | AI26: =F26+G26+P26+Y26+AH26 -> 15897.8 | AJ26: =AI26/E26 -> 0.51818123 | AK26: =(E26-AI26)*$AK$15 -> 1626.042 | AL26: 0 | AM26: 0 | AN26: 0 | AO26: 0 | AP26: 0.05 | AQ26: =AP26*E26 -> 1534 | AR26: =AL26+AM26+AN26+AO26+AQ26 -> 1534 | AS26: =AK26+AR26 -> 3160.042 | AT26: =E26-AS26 -> 27519.958
B27: 05/24 | C27: 060 | D27: PAINEIRA | E27: 29976 | F27: 5288.3 | G27: 2550 | H27: 2 | I27: 24 | J27: 26 | K27: =H27*I27*J27 -> 1248 | L27: 4 | M27: 16 | N27: 16 | O27: =L27*M27*N27 -> 1024 | P27: =K27+O27 -> 2272 | Q27: 2 | R27: 42.5 | S27: 26 | T27: =Q27*R27*S27 -> 2210 | U27: 4 | V27: 42.5 | W27: 16 | X27: =U27*V27*W27 -> 2720 | Y27: =T27+X27 -> 4930 | Z27: 2 | AA27: 80 | AB27: 1 | AC27: =Z27*AA27*AB27 -> 160 | AD27: 4 | AE27: 90 | AF27: 1 | AG27: =AD27*AE27*AF27 -> 360 | AH27: =AC27+AG27 -> 520 | AI27: =F27+G27+P27+Y27+AH27 -> 15560.3 | AJ27: =AI27/E27 -> 0.51909194 | AK27: =(E27-AI27)*$AK$15 -> 1585.727 | AL27: 0 | AM27: 0 | AN27: 0 | AO27: 0 | AP27: 0.0393 | AQ27: =AP27*E27 -> 1178.0568 | AR27: =AL27+AM27+AN27+AO27+AQ27 -> 1178.0568 | AS27: =AK27+AR27 -> 2763.7838 | AT27: =E27-AS27 -> 27212.216
B28: 05/24 | C28: 061 | D28: SUMMER | E28: 30680 | F28: 5625.8 | G28: 2550 | H28: 2 | I28: 24 | J28: 26 | K28: =H28*I28*J28 -> 1248 | L28: 4 | M28: 16 | N28: 16 | O28: =L28*M28*N28 -> 1024 | P28: =K28+O28 -> 2272 | Q28: 2 | R28: 42.5 | S28: 26 | T28: =Q28*R28*S28 -> 2210 | U28: 4 | V28: 42.5 | W28: 16 | X28: =U28*V28*W28 -> 2720 | Y28: =T28+X28 -> 4930 | Z28: 2 | AA28: 80 | AB28: 1 | AC28: =Z28*AA28*AB28 -> 160 | AD28: 4 | AE28: 90 | AF28: 1 | AG28: =AD28*AE28*AF28 -> 360 | AH28: =AC28+AG28 -> 520 | AI28: =F28+G28+P28+Y28+AH28 -> 15897.8 | AJ28: =AI28/E28 -> 0.51818123 | AK28: =(E28-AI28)*$AK$15 -> 1626.042 | AL28: 0 | AM28: 0 | AN28: 0 | AO28: 0 | AP28: 0.0393 | AQ28: =AP28*E28 -> 1205.724 | AR28: =AL28+AM28+AN28+AO28+AQ28 -> 1205.724 | AS28: =AK28+AR28 -> 2831.766 | AT28: =E28-AS28 -> 27848.234
... B35: 09/24 | C35: 068 | D35: SUMMER | E35: 30680 | F35: 5625.8 | G35: 2550 | H35: 2 | I35: 24 | J35: 26 | K35: =H35*I35*J35 -> 1248 | L35: 4 | M35: 16 | N35: 16 | O35: =L35*M35*N35 -> 1024 | P35: =K35+O35 -> 2272 | Q35: 2 | R35: 42.5 | S35: 26 | T35: =Q35*R35*S35 -> 2210 | U35: 4 | V35: 42.5 | W35: 16 | X35: =U35*V35*W35 -> 2720 | Y35: =T35+X35 -> 4930 | Z35: 2 | AA35: 80 | AB35: 1 | AC35: =Z35*AA35*AB35 -> 160 | AD35: 4 | AE35: 90 | AF35: 1 | AG35: =AD35*AE35*AF35 -> 360 | AH35: =AC35+AG35 -> 520 | AI35: =F35+G35+P35+Y35+AH35 -> 15897.8 | AJ35: =AI35/E35 -> 0.51818123 | AK35: =(E35-AI35)*$AK$15 -> 1626.042 | AL35: 0 | AM35: 0 | AN35: 0 | AO35: 0 | AP35: 0.0372 | AQ35: =AP35*E35 -> 1141.296 | AR35: =AL35+AM35+AN35+AO35+AQ35 -> 1141.296 | AS35: =AK35+AR35 -> 2767.338 | AT35: =E35-AS35 -> 27912.662
B36: 10/24 | C36: 70 | D36: SUMMER | E36: 30680 | F36: 5625.8 | G36: 2550 | H36: 2 | I36: 24 | J36: 26 | K36: =H36*I36*J36 -> 1248 | L36: 4 | M36: 16 | N36: 16 | O36: =L36*M36*N36 -> 1024 | P36: =K36+O36 -> 2272 | Q36: 2 | R36: 42.5 | S36: 26 | T36: =Q36*R36*S36 -> 2210 | U36: 4 | V36: 42.5 | W36: 16 | X36: =U36*V36*W36 -> 2720 | Y36: =T36+X36 -> 4930 | Z36: 2 | AA36: 80 | AB36: 1 | AC36: =Z36*AA36*AB36 -> 160 | AD36: 4 | AE36: 90 | AF36: 1 | AG36: =AD36*AE36*AF36 -> 360 | AH36: =AC36+AG36 -> 520 | AI36: =F36+G36+P36+Y36+AH36 -> 15897.8 | AJ36: =AI36/E36 -> 0.51818123 | AK36: =(E36-AI36)*$AK$15 -> 1626.042 | AL36: 0 | AM36: 0 | AN36: 0 | AO36: 0 | AP36: 0.0366 | AQ36: =AP36*E36 -> 1122.888 | AR36: =AL36+AM36+AN36+AO36+AQ36 -> 1122.888 | AS36: =AK36+AR36 -> 2748.93 | AT36: =E36-AS36 -> 27931.07
B37: 10/24 | C37: 69 | D37: TAJ MAHAL_GO | E37: 37805 | F37: 6980 | G37: 4760 | H37: 6 | I37: 24 | J37: 26 | K37: =H37*I37*J37 -> 3744 | L37: 0 | M37: 0 | N37: 0 | O37: =L37*M37*N37 -> 0 | P37: =K37+O37 -> 3744 | Q37: 6 | R37: 42.5 | S37: 26 | T37: =Q37*R37*S37 -> 6630 | U37: 0 | V37: 0 | W37: 0 | X37: =U37*V37*W37 -> 0 | Y37: =T37+X37 -> 6630 | Z37: 6 | AA37: 90 | AB37: 2 | AC37: =Z37*AA37*AB37 -> 1080 | AD37: 0 | AE37: 0 | AF37: 0 | AG37: =AD37*AE37*AF37 -> 0 | AH37: =AC37+AG37 -> 1080 | AI37: =F37+G37+P37+Y37+AH37 -> 23194 | AJ37: =AI37/E37 -> 0.61351673 | AK37: =(E37-AI37)*$AK$15 -> 1607.21 | AL37: 0 | AM37: 0 | AN37: 0 | AO37: 0 | AP37: 0 | AQ37: =AP37*E37 -> 0 | AR37: =AL37+AM37+AN37+AO37+AQ37 -> 0 | AS37: =AK37+AR37 -> 1607.21 | AT37: =E37-AS37 -> 36197.79 | AV37: 32240.097 | AW37: =AT37-AV37 -> 3957.6925
B38: 10/24 | C38: 71 | D38: TAJ MAHAL CONSTRUÇÃO E INCORPORAÇÃO_GO | E38: 1372 | F38: 472.7 | G38: 132 | H38: 1 | I38: 24 | J38: 4 | K38: =H38*I38*J38 -> 96 | L38: 0 | M38: 0 | N38: 0 | O38: =L38*M38*N38 -> 0 | P38: =K38+O38 -> 96 | Q38: 1 | R38: 42.5 | S38: 4 | T38: =Q38*R38*S38 -> 170 | U38: 0 | V38: 0 | W38: 0 | X38: =U38*V38*W38 -> 0 | Y38: =T38+X38 -> 170 | Z38: 1 | AA38: 80 | AB38: 2 | AC38: =Z38*AA38*AB38 -> 160 | AD38: 0 | AE38: 0 | AF38: 0 | AG38: =AD38*AE38*AF38 -> 0 | AH38: =AC38+AG38 -> 160 | AI38: =F38+G38+P38+Y38+AH38 -> 1030.7 | AJ38: =AI38/E38 -> 0.75123907 | AK38: =(E38-AI38)*$AK$15 -> 37.543 | AL38: 0 | AM38: 0 | AN38: 0 | AO38: 0 | AP38: 0 | AQ38: =AP38*E38 -> 0 | AR38: =AL38+AM38+AN38+AO38+AQ38 -> 0 | AS38: =AK38+AR38 -> 37.543 | AT38: =E38-AS38 -> 1334.457
B39: 11/24 | C39: 72 | D39: SUMMER | E39: 30680 | F39: 5625.8 | G39: 2550 | H39: 2 | I39: 24 | J39: 26 | K39: =H39*I39*J39 -> 1248 | L39: 4 | M39: 16 | N39: 16 | O39: =L39*M39*N39 -> 1024 | P39: =K39+O39 -> 2272 | Q39: 2 | R39: 42.5 | S39: 26 | T39: =Q39*R39*S39 -> 2210 | U39: 4 | V39: 42.5 | W39: 16 | X39: =U39*V39*W39 -> 2720 | Y39: =T39+X39 -> 4930 | Z39: 2 | AA39: 80 | AB39: 1 | AC39: =Z39*AA39*AB39 -> 160 | AD39: 4 | AE39: 90 | AF39: 1 | AG39: =AD39*AE39*AF39 -> 360 | AH39: =AC39+AG39 -> 520 | AI39: =F39+G39+P39+Y39+AH39 -> 15897.8 | AJ39: =AI39/E39 -> 0.51818123 | AK39: =(E39-AI39)*$AK$15 -> 1626.042 | AL39: 0 | AM39: 0 | AN39: 0 | AO39: 0 | AP39: 0.03520013 | AQ39: =AP39*E39 -> 1079.94 | AR39: =AL39+AM39+AN39+AO39+AQ39 -> 1079.94 | AS39: =AK39+AR39 -> 2705.982 | AT39: =E39-AS39 -> 27974.018 | AV39: 1079.94 | AW39: =AV39/E39 -> 0.03520013
B40: 11/24 | C40: 77 | D40: TAJ MAHAL_GO | E40: 37805 | F40: 6980 | G40: 4760 | H40: 6 | I40: 24 | J40: 26 | K40: =H40*I40*J40 -> 3744 | L40: 0 | M40: 0 | N40: 0 | O40: =L40*M40*N40 -> 0 | P40: =K40+O40 -> 3744 | Q40: 6 | R40: 42.5 | S40: 26 | T40: =Q40*R40*S40 -> 6630 | U40: 0 | V40: 0 | W40: 0 | X40: =U40*V40*W40 -> 0 | Y40: =T40+X40 -> 6630 | Z40: 6 | AA40: 90 | AB40: 2 | AC40: =Z40*AA40*AB40 -> 1080 | AD40: 0 | AE40: 0 | AF40: 0 | AG40: =AD40*AE40*AF40 -> 0 | AH40: =AC40+AG40 -> 1080 | AI40: =F40+G40+P40+Y40+AH40 -> 23194 | AJ40: =AI40/E40 -> 0.61351673 | AK40: =(E40-AI40)*$AK$15 -> 1607.21 | AL40: 0 | AM40: 0 | AN40: 0 | AO40: 0 | AP40: 0 | AQ40: =AP40*E40 -> 0 | AR40: =AL40+AM40+AN40+AO40+AQ40 -> 0 | AS40: =AK40+AR40 -> 1607.21 | AT40: =E40-AS40 -> 36197.79 | AV40: 32240.097 | AW40: =AT40-AV40 -> 3957.6925
B41: 11/24 | C41: 76 | D41: TAJ MAHAL CONSTRUÇÃO E INCORPORAÇÃO_GO | E41: 1372 | F41: 320 | G41: 0 | H41: 1 | I41: 24 | J41: 4 | K41: =H41*I41*J41 -> 96 | L41: 0 | M41: 0 | N41: 0 | O41: =L41*M41*N41 -> 0 | P41: =K41+O41 -> 96 | Q41: 1 | R41: 42.5 | S41: 4 | T41: =Q41*R41*S41 -> 170 | U41: 0 | V41: 0 | W41: 0 | X41: =U41*V41*W41 -> 0 | Y41: =T41+X41 -> 170 | Z41: 1 | AA41: 80 | AB41: 1 | AC41: =Z41*AA41*AB41 -> 80 | AD41: 0 | AE41: 0 | AF41: 0 | AG41: =AD41*AE41*AF41 -> 0 | AH41: =AC41+AG41 -> 80 | AI41: =F41+G41+P41+Y41+AH41 -> 666 | AJ41: =AI41/E41 -> 0.48542274 | AK41: =(E41-AI41)*$AK$15 -> 77.66 | AL41: 0 | AM41: 0 | AN41: 0 | AO41: 0 | AP41: 0 | AQ41: =AP41*E41 -> 0 | AR41: =AL41+AM41+AN41+AO41+AQ41 -> 0 | AS41: =AK41+AR41 -> 77.66 | AT41: =E41-AS41 -> 1294.34
B42: 11/24 | C42: 79 | D42: AGROBRASIL_GO | E42: 20712 | F42: 799 | G42: 490 | H42: 4 | I42: 24 | J42: 26 | K42: =H42*I42*J42 -> 2496 | L42: 0 | M42: 0 | N42: 0 | O42: =L42*M42*N42 -> 0 | P42: =K42+O42 -> 2496 | Q42: 4 | R42: 42.5 | S42: 26 | T42: =Q42*R42*S42 -> 4420 | U42: 0 | V42: 0 | W42: 0 | X42: =U42*V42*W42 -> 0 | Y42: =T42+X42 -> 4420 | Z42: 4 | AA42: 90 | AB42: 2 | AC42: =Z42*AA42*AB42 -> 720 | AD42: 0 | AE42: 0 | AF42: 0 | AG42: =AD42*AE42*AF42 -> 0 | AH42: =AC42+AG42 -> 720 | AI42: =F42+G42+P42+Y42+AH42 -> 8925 | AJ42: =AI42/E42 -> 0.43090962 | AK42: =(E42-AI42)*$AK$15 -> 1296.57 | AL42: 0 | AM42: 0 | AN42: 0 | AO42: 0 | AP42: 0 | AQ42: =AP42*E42 -> 0 | AR42: =AL42+AM42+AN42+AO42+AQ42 -> 0 | AS42: =AK42+AR42 -> 1296.57 | AT42: =E42-AS42 -> 19415.43
B43: 12/24 | C43: 80 | D43: SUMMER | E43: 30680 | F43: 5625.8 | G43: 2550 | H43: 2 | I43: 24 | J43: 26 | K43: =H43*I43*J43 -> 1248 | L43: 4 | M43: 16 | N43: 16 | O43: =L43*M43*N43 -> 1024 | P43: =K43+O43 -> 2272 | Q43: 2 | R43: 42.5 | S43: 26 | T43: =Q43*R43*S43 -> 2210 | U43: 4 | V43: 42.5 | W43: 16 | X43: =U43*V43*W43 -> 2720 | Y43: =T43+X43 -> 4930 | Z43: 2 | AA43: 80 | AB43: 1 | AC43: =Z43*AA43*AB43 -> 160 | AD43: 4 | AE43: 90 | AF43: 1 | AG43: =AD43*AE43*AF43 -> 360 | AH43: =AC43+AG43 -> 520 | AI43: =F43+G43+P43+Y43+AH43 -> 15897.8 | AJ43: =AI43/E43 -> 0.51818123 | AK43: =(E43-AI43)*$AK$15 -> 1626.042 | AL43: 0 | AM43: 0 | AN43: 0 | AO43: 0 | AP43: 0.0348 | AQ43: =AP43*E43 -> 1067.664 | AR43: =AL43+AM43+AN43+AO43+AQ43 -> 1067.664 | AS43: =AK43+AR43 -> 2693.706 | AT43: =E43-AS43 -> 27986.294
B44: 12/24 | C44: 81 | D44: TAJ MAHAL_GO | E44: 37805 | F44: 6980 | G44: 4760 | H44: 6 | I44: 24 | J44: 26 | K44: =H44*I44*J44 -> 3744 | L44: 0 | M44: 0 | N44: 0 | O44: =L44*M44*N44 -> 0 | P44: =K44+O44 -> 3744 | Q44: 6 | R44: 42.5 | S44: 26 | T44: =Q44*R44*S44 -> 6630 | U44: 0 | V44: 0 | W44: 0 | X44: =U44*V44*W44 -> 0 | Y44: =T44+X44 -> 6630 | Z44: 6 | AA44: 90 | AB44: 2 | AC44: =Z44*AA44*AB44 -> 1080 | AD44: 0 | AE44: 0 | AF44: 0 | AG44: =AD44*AE44*AF44 -> 0 | AH44: =AC44+AG44 -> 1080 | AI44: =F44+G44+P44+Y44+AH44 -> 23194 | AJ44: =AI44/E44 -> 0.61351673 | AK44: =(E44-AI44)*$AK$15 -> 1607.21 | AL44: 0 | AM44: 0 | AN44: 0 | AO44: 0 | AP44: 0 | AQ44: =AP44*E44 -> 0 | AR44: =AL44+AM44+AN44+AO44+AQ44 -> 0 | AS44: =AK44+AR44 -> 1607.21 | AT44: =E44-AS44 -> 36197.79
B45: 12/24 | C45: 82 | D45: TAJ MAHAL CONSTRUÇÃO E INCORPORAÇÃO_GO | E45: 1372 | F45: 320 | G45: 0 | H45: 1 | I45: 24 | J45: 4 | K45: =H45*I45*J45 -> 96 | L45: 0 | M45: 0 | N45: 0 | O45: =L45*M45*N45 -> 0 | P45: =K45+O45 -> 96 | Q45: 1 | R45: 42.5 | S45: 4 | T45: =Q45*R45*S45 -> 170 | U45: 0 | V45: 0 | W45: 0 | X45: =U45*V45*W45 -> 0 | Y45: =T45+X45 -> 170 | Z45: 1 | AA45: 80 | AB45: 1 | AC45: =Z45*AA45*AB45 -> 80 | AD45: 0 | AE45: 0 | AF45: 0 | AG45: =AD45*AE45*AF45 -> 0 | AH45: =AC45+AG45 -> 80 | AI45: =F45+G45+P45+Y45+AH45 -> 666 | AJ45: =AI45/E45 -> 0.48542274 | AK45: =(E45-AI45)*$AK$15 -> 77.66 | AL45: 0 | AM45: 0 | AN45: 0 | AO45: 0 | AP45: 0 | AQ45: =AP45*E45 -> 0 | AR45: =AL45+AM45+AN45+AO45+AQ45 -> 0 | AS45: =AK45+AR45 -> 77.66 | AT45: =E45-AS45 -> 1294.34
B46: 12/24 | C46: 83 | D46: AGROBRASIL_GO | E46: 20712 | F46: 799 | G46: 490 | H46: 4 | I46: 24 | J46: 26 | K46: =H46*I46*J46 -> 2496 | L46: 0 | M46: 0 | N46: 0 | O46: =L46*M46*N46 -> 0 | P46: =K46+O46 -> 2496 | Q46: 4 | R46: 42.5 | S46: 26 | T46: =Q46*R46*S46 -> 4420 | U46: 0 | V46: 0 | W46: 0 | X46: =U46*V46*W46 -> 0 | Y46: =T46+X46 -> 4420 | Z46: 4 | AA46: 90 | AB46: 2 | AC46: =Z46*AA46*AB46 -> 720 | AD46: 0 | AE46: 0 | AF46: 0 | AG46: =AD46*AE46*AF46 -> 0 | AH46: =AC46+AG46 -> 720 | AI46: =F46+G46+P46+Y46+AH46 -> 8925 | AJ46: =AI46/E46 -> 0.43090962 | AK46: =(E46-AI46)*$AK$15 -> 1296.57 | AL46: 0 | AM46: 0 | AN46: 0 | AO46: 0 | AP46: 0 | AQ46: =AP46*E46 -> 0 | AR46: =AL46+AM46+AN46+AO46+AQ46 -> 0 | AS46: =AK46+AR46 -> 1296.57 | AT46: =E46-AS46 -> 19415.43
B47: 12/24 | C47: 84 | D47: BELA VISTA | E47: =5300+530 -> 5830 | F47: 950.61 | G47: 351.9 | H47: 1 | I47: 24 | J47: 26 | K47: =H47*I47*J47 -> 624 | L47: 0 | M47: 0 | N47: 0 | O47: =L47*M47*N47 -> 0 | P47: =K47+O47 -> 624 | Q47: 1 | R47: 42.5 | S47: 26 | T47: =Q47*R47*S47 -> 1105 | U47: 0 | V47: 0 | W47: 0 | X47: =U47*V47*W47 -> 0 | Y47: =T47+X47 -> 1105 | Z47: 1 | AA47: 90 | AB47: 2 | AC47: =Z47*AA47*AB47 -> 180 | AD47: 0 | AE47: 0 | AF47: 0 | AG47: =AD47*AE47*AF47 -> 0 | AH47: =AC47+AG47 -> 180 | AI47: =F47+G47+P47+Y47+AH47 -> 3211.51 | AJ47: =AI47/E47 -> 0.55085935 | AK47: =(E47-AI47)*$AK$15 -> 288.0339 | AL47: 0 | AM47: 0 | AN47: 0 | AO47: 0 | AP47: 0.0348 | AQ47: =AP47*E47 -> 202.884 | AR47: =AL47+AM47+AN47+AO47+AQ47 -> 202.884 | AS47: =AK47+AR47 -> 490.9179 | AT47: =E47-AS47 -> 5339.0821
B48: 12/24 | C48: 85 | D48: VICENZA_GO | E48: =(7820/30)*16 -> 4170.6667 | F48: 290 | G48: 130 | H48: 2 | I48: 24 | J48: 16 | K48: =H48*I48*J48 -> 768 | L48: 0 | M48: 0 | N48: 0 | O48: =L48*M48*N48 -> 0 | P48: =K48+O48 -> 768 | Q48: 2 | R48: 42.5 | S48: 16 | T48: =Q48*R48*S48 -> 1360 | U48: 0 | V48: 0 | W48: 0 | X48: =U48*V48*W48 -> 0 | Y48: =T48+X48 -> 1360 | Z48: 2 | AA48: 90 | AB48: 2 | AC48: =Z48*AA48*AB48 -> 360 | AD48: 0 | AE48: 0 | AF48: 0 | AG48: =AD48*AE48*AF48 -> 0 | AH48: =AC48+AG48 -> 360 | AI48: =F48+G48+P48+Y48+AH48 -> 2908 | AJ48: =AI48/E48 -> 0.69725064 | AK48: =(E48-AI48)*$AK$15 -> 138.89333 | AL48: 0 | AM48: 0 | AN48: 0 | AO48: 0 | AP48: 0 | AQ48: =AP48*E48 -> 0 | AR48: =AL48+AM48+AN48+AO48+AQ48 -> 0 | AS48: =AK48+AR48 -> 138.89333 | AT48: =E48-AS48 -> 4031.7733
B49: 01/25 | C49: 91 | D49: SUMMER | E49: 30680 | F49: 5625.8 | G49: 2550 | H49: 2 | I49: 24 | J49: 26 | K49: =H49*I49*J49 -> 1248 | L49: 4 | M49: 16 | N49: 16 | O49: =L49*M49*N49 -> 1024 | P49: =K49+O49 -> 2272 | Q49: 2 | R49: 42.5 | S49: 26 | T49: =Q49*R49*S49 -> 2210 | U49: 4 | V49: 42.5 | W49: 16 | X49: =U49*V49*W49 -> 2720 | Y49: =T49+X49 -> 4930 | Z49: 2 | AA49: 80 | AB49: 1 | AC49: =Z49*AA49*AB49 -> 160 | AD49: 4 | AE49: 90 | AF49: 1 | AG49: =AD49*AE49*AF49 -> 360 | AH49: =AC49+AG49 -> 520 | AI49: =F49+G49+P49+Y49+AH49 -> 15897.8 | AJ49: =AI49/E49 -> 0.51818123 | AK49: =(E49-AI49)*$AK$15 -> 1626.042 | AL49: 0 | AM49: 0 | AN49: 0 | AO49: 0 | AP49: 0.05 | AQ49: =AP49*E49 -> 1534 | AR49: =AL49+AM49+AN49+AO49+AQ49 -> 1534 | AS49: =AK49+AR49 -> 3160.042 | AT49: =E49-AS49 -> 27519.958
...

Sheet 2026_RECEITA_JJB ADM
B1: JJ BARBOSA ADMINISTRAÇÃO
B2: RECEITA
B4: CNAE-Fiscal: | D4: N812140000 _ LIMPEZA EM PREDIOS E EM DOMICILIOS
B5: ATIVIDADE MUNICIPIO: | D5: 710 - 7.10 - Limpeza, manutenção e conservação de vias e logradouros
B7: ANO: | C7: 2026 | D7: VERSÃO 2024.11.20
B8: CLIENTE: | C8: JJ BARBOSA ADMINISTRAÇÃO | E8: REGIME DE TRIBUTAÇÃO: | F8: SIMPLES NACIONAL
B9: CNPJ: | C9: 41.106.556/0001-44
B10: ENDEREÇO: | C10: ÁGUAS CLARAS
B11: TOTAL | C11: =E127 -> 50761
B13: COMP | C13: NF | D13: CLIENTE | E13: VALOR TOTAL DOS SERVIÇOS | F13: MATERIAS | G13: EQUIPAMENTOS | H13: VALE TRANSPORTE | Q13: VALE ALIMENTAÇÃO | Z13: UNIFORME | AI13: TOTAL BASE RETENÇÃO INSS | AJ13: BASE CÁCULO INSS | AK13: RETENÇÃO DESTACADO NA NF | AS13: TOTAL RETENÇÃO NF | AT13: VALOR LIQUIDO DA NOTA FISCAL
H14: 44H/S | L14: 12 X 36 | P14: TOTAL | Q14: 44H/S | U14: 12 X 36 | Y14: TOTAL | Z14: 44H/S | AD14: 12 X 36 | AH14: TOTAL | AK14: GPS 2632 | AL14: IRRJ 1001 | AM14: CSLL 1002 | AN14: COFINS 1004 | AO14: PIS 1005 | AP14: ISSQN 1732 | AR14: TOTAL
H15: QTDE | I15: $ UNIT | J15: DIAS | K15: TOTAL | L15: QTDE | M15: $ UNIT | N15: DIAS | O15: TOTAL | Q15: QTDE | R15: $ UNIT | S15: DIAS | T15: TOTAL | U15: QTDE | V15: $ UNIT | W15: DIAS | X15: TOTAL | Z15: QTDE | AA15: $ UNIT | AB15: ANO | AC15: TOTAL | AD15: QTDE | AE15: $ UNIT | AF15: ANO | AG15: TOTAL | AJ15: % | AK15: 0.11 | AL15: 0 | AM15: 0 | AN15: 0 | AO15: 0 | AP15: % | AQ15: $ | AR15: =SUBTOTAL(9,AL15:AQ15) -> 0 | AS15: =AK15+AR15 -> 0.11
B17: 01/24 | C17: 63 GRENWAY | D17: PORTO SEGURO | E17: 26672 | F17: 3022.7 | G17: 5470 | H17: 2 | I17: 16 | J17: 26 | K17: =H17*I17*J17 -> 832 | L17: 4 | M17: 16 | N17: 16 | O17: =L17*M17*N17 -> 1024 | P17: =K17+O17 -> 1856 | Q17: 2 | R17: 40.5 | S17: 26 | T17: =Q17*R17*S17 -> 2106 | U17: 4 | V17: 40.5 | W17: 16 | X17: =U17*V17*W17 -> 2592 | Y17: =T17+X17 -> 4698 | Z17: 2 | AA17: 80 | AB17: 1 | AC17: =Z17*AA17*AB17 -> 160 | AD17: 4 | AE17: 90 | AF17: 1 | AG17: =AD17*AE17*AF17 -> 360 | AH17: =AC17+AG17 -> 520 | AI17: =F17+G17+P17+Y17+AH17 -> 15566.7 | AJ17: =AI17/E17 -> 0.58363452 | AK17: =(E17-AI17)*$AK$15 -> 1221.583 | AL17: 0 | AM17: 0 | AN17: 0 | AO17: 0 | AP17: 0 | AQ17: =AP17*E17 -> 0 | AR17: =AL17+AM17+AN17+AO17+AQ17 -> 0 | AS17: =AK17+AR17 -> 1221.583 | AT17: =E17-AS17 -> 25450.417
B18: 01/24 | C18: 64 GRENWAY | D18: RPR 01 | E18: 10999 | F18: 1531.4 | G18: 2040 | H18: 2 | I18: 16 | J18: 26 | K18: =H18*I18*J18 -> 832 | L18: 0 | M18: 0 | N18: 0 | O18: =L18*M18*N18 -> 0 | P18: =K18+O18 -> 832 | Q18: 2 | R18: 40.5 | S18: 26 | T18: =Q18*R18*S18 -> 2106 | U18: 0 | V18: 0 | W18: 0 | X18: =U18*V18*W18 -> 0 | Y18: =T18+X18 -> 2106 | Z18: 2 | AA18: 80 | AB18: 1 | AC18: =Z18*AA18*AB18 -> 160 | AD18: 0 | AE18: 0 | AF18: 0 | AG18: =AD18*AE18*AF18 -> 0 | AH18: =AC18+AG18 -> 160 | AI18: =F18+G18+P18+Y18+AH18 -> 6669.4 | AJ18: =AI18/E18 -> 0.60636421 | AK18: =(E18-AI18)*$AK$15 -> 476.256 | AL18: 0 | AM18: 0 | AN18: 0 | AO18: 0 | AP18: 0.05 | AQ18: =AP18*E18 -> 549.95 | AR18: =AL18+AM18+AN18+AO18+AQ18 -> 549.95 | AS18: =AK18+AR18 -> 1026.206 | AT18: =E18-AS18 -> 9972.794
B19: 01/24 | C19: 66 GRENWAY | D19: SHCES 509 BL B | E19: 4920 | F19: 0 | G19: 0 | H19: 1 | I19: 16 | J19: 26 | K19: =H19*I19*J19 -> 416 | L19: 0 | M19: 0 | N19: 0 | O19: =L19*M19*N19 -> 0 | P19: =K19+O19 -> 416 | Q19: 1 | R19: 40.5 | S19: 26 | T19: =Q19*R19*S19 -> 1053 | U19: 0 | V19: 0 | W19: 0 | X19: =U19*V19*W19 -> 0 | Y19: =T19+X19 -> 1053 | Z19: 0 | AA19: 0 | AB19: 0 | AC19: =Z19*AA19*AB19 -> 0 | AD19: 0 | AE19: 0 | AF19: 0 | AG19: =AD19*AE19*AF19 -> 0 | AH19: =AC19+AG19 -> 0 | AI19: =F19+G19+P19+Y19+AH19 -> 1469 | AJ19: =AI19/E19 -> 0.29857724 | AK19: 379.33 | AL19: 0 | AM19: 0 | AN19: 0 | AO19: 0 | AP19: 0.05 | AQ19: =AP19*E19 -> 246 | AR19: =AL19+AM19+AN19+AO19+AQ19 -> 246 | AS19: =AK19+AR19 -> 625.33 | AT19: =E19-AS19 -> 4294.67
B20: 02/24 | C20: 67 | D20: SHCES 509 BL B | E20: 5392 | F20: 0 | G20: 0 | H20: 1 | I20: 19.53 | J20: 26 | K20: =H20*I20*J20 -> 507.78 | L20: 0 | M20: 0 | N20: 0 | O20: =L20*M20*N20 -> 0 | P20: =K20+O20 -> 507.78 | Q20: 1 | R20: 42.5 | S20: 26 | T20: =Q20*R20*S20 -> 1105 | U20: 0 | V20: 0 | W20: 0 | X20: =U20*V20*W20 -> 0 | Y20: =T20+X20 -> 1105 | Z20: 0 | AA20: 0 | AB20: 0 | AC20: =Z20*AA20*AB20 -> 0 | AD20: 0 | AE20: 0 | AF20: 0 | AG20: =AD20*AE20*AF20 -> 0 | AH20: =AC20+AG20 -> 0 | AI20: =F20+G20+P20+Y20+AH20 -> 1612.78 | AJ20: =AI20/E20 -> 0.29910608 | AK20: =(E20-AI20)*$AK$15 -> 415.7142 | AL20: 0 | AM20: 0 | AN20: 0 | AO20: 0 | AP20: 0.031700668 | AQ20: =AP20*E20 -> 170.93 | AR20: =AL20+AM20+AN20+AO20+AQ20 -> 170.93 | AS20: =AK20+AR20 -> 586.6442 | AT20: =E20-AS20 -> 4805.3558
B21: 02/24 | C21: 69 | D21: RPR 01 | E21: 11906 | F21: 1977.4 | G21: 2040 | H21: 2 | I21: 16 | J21: 26 | K21: =H21*I21*J21 -> 832 | L21: 0 | M21: 0 | N21: 0 | O21: =L21*M21*N21 -> 0 | P21: =K21+O21 -> 832 | Q21: 2 | R21: 42.5 | S21: 26 | T21: =Q21*R21*S21 -> 2210 | U21: 0 | V21: 0 | W21: 0 | X21: =U21*V21*W21 -> 0 | Y21: =T21+X21 -> 2210 | Z21: 2 | AA21: 80 | AB21: 1 | AC21: =Z21*AA21*AB21 -> 160 | AD21: 0 | AE21: 0 | AF21: 0 | AG21: =AD21*AE21*AF21 -> 0 | AH21: =AC21+AG21 -> 160 | AI21: =F21+G21+P21+Y21+AH21 -> 7219.4 | AJ21: =AI21/E21 -> 0.60636654 | AK21: =(E21-AI21)*$AK$15 -> 515.526 | AL21: 0 | AM21: 0 | AN21: 0 | AO21: 0 | AP21: 0.031700668 | AQ21: =AP21*E21 -> 377.42815 | AR21: =AL21+AM21+AN21+AO21+AQ21 -> 377.42815 | AS21: =AK21+AR21 -> 892.95415 | AT21: =E21-AS21 -> 11013.046
B22: 02/24 | C22: 71 | D22: PORTO SEGURO | E22: 28822 | F22: 2042.9 | G22: 2915 | H22: 2 | I22: 24 | J22: 26 | K22: =H22*I22*J22 -> 1248 | L22: 4 | M22: 16 | N22: 16 | O22: =L22*M22*N22 -> 1024 | P22: =K22+O22 -> 2272 | Q22: 2 | R22: 42.5 | S22: 26 | T22: =Q22*R22*S22 -> 2210 | U22: 4 | V22: 42.5 | W22: 16 | X22: =U22*V22*W22 -> 2720 | Y22: =T22+X22 -> 4930 | Z22: 2 | AA22: 80 | AB22: 1 | AC22: =Z22*AA22*AB22 -> 160 | AD22: 4 | AE22: 90 | AF22: 1 | AG22: =AD22*AE22*AF22 -> 360 | AH22: =AC22+AG22 -> 520 | AI22: =F22+G22+P22+Y22+AH22 -> 12679.9 | AJ22: =AI22/E22 -> 0.43993824 | AK22: =(E22-AI22)*$AK$15 -> 1775.631 | AL22: 0 | AM22: 0 | AN22: 0 | AO22: 0 | AP22: 0.031700668 | AQ22: =AP22*E22 -> 913.67664 | AR22: =AL22+AM22+AN22+AO22+AQ22 -> 913.67664 | AS22: =AK22+AR22 -> 2689.3076 | AT22: =E22-AS22 -> 26132.692
B23: 02/24 | C23: 72 | D23: PORTO SEGURO | E23: 2150 | F23: 945.87 | G23: 0 | H23: 0 | I23: 0 | J23: 0 | K23: =H23*I23*J23 -> 0 | L23: 0 | M23: 0 | N23: 0 | O23: =L23*M23*N23 -> 0 | P23: =K23+O23 -> 0 | Q23: 0 | R23: 0 | S23: 0 | T23: =Q23*R23*S23 -> 0 | U23: 0 | V23: 0 | W23: 0 | X23: =U23*V23*W23 -> 0 | Y23: =T23+X23 -> 0 | Z23: 0 | AA23: 0 | AB23: 0 | AC23: =Z23*AA23*AB23 -> 0 | AD23: 0 | AE23: 0 | AF23: 0 | AG23: =AD23*AE23*AF23 -> 0 | AH23: =AC23+AG23 -> 0 | AI23: =F23+G23+P23+Y23+AH23 -> 945.87 | AJ23: =AI23/E23 -> 0.43993953 | AK23: =(E23-AI23)*$AK$15 -> 132.4543 | AL23: 0 | AM23: 0 | AN23: 0 | AO23: 0 | AP23: 0.031700668 | AQ23: =AP23*E23 -> 68.156435 | AR23: =AL23+AM23+AN23+AO23+AQ23 -> 68.156435 | AS23: =AK23+AR23 -> 200.61074 | AT23: =E23-AS23 -> 1949.3893
B24: 02/24 | C24: 73 | D24: RPR 01 | E24: 907 | F24: 549.97 | G24: 0 | H24: 0 | I24: 0 | J24: 0 | K24: =H24*I24*J24 -> 0 | L24: 0 | M24: 0 | N24: 0 | O24: =L24*M24*N24 -> 0 | P24: =K24+O24 -> 0 | Q24: 0 | R24: 0 | S24: 0 | T24: =Q24*R24*S24 -> 0 | U24: 0 | V24: 0 | W24: 0 | X24: =U24*V24*W24 -> 0 | Y24: =T24+X24 -> 0 | Z24: 0 | AA24: 0 | AB24: 0 | AC24: =Z24*AA24*AB24 -> 0 | AD24: 0 | AE24: 0 | AF24: 0 | AG24: =AD24*AE24*AF24 -> 0 | AH24: =AC24+AG24 -> 0 | AI24: =F24+G24+P24+Y24+AH24 -> 549.97 | AJ24: =AI24/E24 -> 0.60636163 | AK24: =(E24-AI24)*$AK$15 -> 39.2733 | AL24: 0 | AM24: 0 | AN24: 0 | AO24: 0 | AP24: 0.031700668 | AQ24: =AP24*E24 -> 28.752506 | AR24: =AL24+AM24+AN24+AO24+AQ24 -> 28.752506 | AS24: =AK24+AR24 -> 68.025806 | AT24: =E24-AS24 -> 838.97419
B25: 02/24 | C25: 74 | D25: SHCES 509 BL B | E25: 472 | F25: 141.18 | G25: 0 | H25: 0 | I25: 0 | J25: 0 | K25: =H25*I25*J25 -> 0 | L25: 0 | M25: 0 | N25: 0 | O25: =L25*M25*N25 -> 0 | P25: =K25+O25 -> 0 | Q25: 0 | R25: 0 | S25: 0 | T25: =Q25*R25*S25 -> 0 | U25: 0 | V25: 0 | W25: 0 | X25: =U25*V25*W25 -> 0 | Y25: =T25+X25 -> 0 | Z25: 0 | AA25: 0 | AB25: 0 | AC25: =Z25*AA25*AB25 -> 0 | AD25: 0 | AE25: 0 | AF25: 0 | AG25: =AD25*AE25*AF25 -> 0 | AH25: =AC25+AG25 -> 0 | AI25: =F25+G25+P25+Y25+AH25 -> 141.18 | AJ25: =AI25/E25 -> 0.29911017 | AK25: =(E25-AI25)*$AK$15 -> 36.3902 | AL25: 0 | AM25: 0 | AN25: 0 | AO25: 0 | AP25: 0.031700668 | AQ25: =AP25*E25 -> 14.962715 | AR25: =AL25+AM25+AN25+AO25+AQ25 -> 14.962715 | AS25: =AK25+AR25 -> 51.352915 | AT25: =E25-AS25 -> 420.64708
B26: 03/24 | C26: 75 | D26: SHCES 509 BL B | E26: 5392 | F26: 0 | G26: 0 | H26: 1 | I26: 19.53 | J26: 26 | K26: =H26*I26*J26 -> 507.78 | L26: 0 | M26: 0 | N26: 0 | O26: =L26*M26*N26 -> 0 | P26: =K26+O26 -> 507.78 | Q26: 1 | R26: 42.5 | S26: 26 | T26: =Q26*R26*S26 -> 1105 | U26: 0 | V26: 0 | W26: 0 | X26: =U26*V26*W26 -> 0 | Y26: =T26+X26 -> 1105 | Z26: 0 | AA26: 0 | AB26: 0 | AC26: =Z26*AA26*AB26 -> 0 | AD26: 0 | AE26: 0 | AF26: 0 | AG26: =AD26*AE26*AF26 -> 0 | AH26: =AC26+AG26 -> 0 | AI26: =F26+G26+P26+Y26+AH26 -> 1612.78 | AJ26: =AI26/E26 -> 0.29910608 | AK26: =(E26-AI26)*$AK$15 -> 415.7142 | AL26: 0 | AM26: 0 | AN26: 0 | AO26: 0 | AP26: 0.031700668 | AQ26: =AP26*E26 -> 170.93 | AR26: =AL26+AM26+AN26+AO26+AQ26 -> 170.93 | AS26: =AK26+AR26 -> 586.6442 | AT26: =E26-AS26 -> 4805.3558
B27: 03/24 | C27: 76 | D27: RPR 01 | E27: 11906 | F27: 1977.4 | G27: 2040 | H27: 2 | I27: 16 | J27: 26 | K27: =H27*I27*J27 -> 832 | L27: 0 | M27: 0 | N27: 0 | O27: =L27*M27*N27 -> 0 | P27: =K27+O27 -> 832 | Q27: 2 | R27: 42.5 | S27: 26 | T27: =Q27*R27*S27 -> 2210 | U27: 0 | V27: 0 | W27: 0 | X27: =U27*V27*W27 -> 0 | Y27: =T27+X27 -> 2210 | Z27: 2 | AA27: 80 | AB27: 1 | AC27: =Z27*AA27*AB27 -> 160 | AD27: 0 | AE27: 0 | AF27: 0 | AG27: =AD27*AE27*AF27 -> 0 | AH27: =AC27+AG27 -> 160 | AI27: =F27+G27+P27+Y27+AH27 -> 7219.4 | AJ27: =AI27/E27 -> 0.60636654 | AK27: =(E27-AI27)*$AK$15 -> 515.526 | AL27: 0 | AM27: 0 | AN27: 0 | AO27: 0 | AP27: 0.031700668 | AQ27: =AP27*E27 -> 377.42815 | AR27: =AL27+AM27+AN27+AO27+AQ27 -> 377.42815 | AS27: =AK27+AR27 -> 892.95415 | AT27: =E27-AS27 -> 11013.046
B28: 03/24 | C28: 77 | D28: PORTO SEGURO | E28: 28822 | F28: 2042.9 | G28: 2915 | H28: 2 | I28: 24 | J28: 26 | K28: =H28*I28*J28 -> 1248 | L28: 4 | M28: 16 | N28: 16 | O28: =L28*M28*N28 -> 1024 | P28: =K28+O28 -> 2272 | Q28: 2 | R28: 42.5 | S28: 26 | T28: =Q28*R28*S28 -> 2210 | U28: 4 | V28: 42.5 | W28: 16 | X28: =U28*V28*W28 -> 2720 | Y28: =T28+X28 -> 4930 | Z28: 2 | AA28: 80 | AB28: 1 | AC28: =Z28*AA28*AB28 -> 160 | AD28: 4 | AE28: 90 | AF28: 1 | AG28: =AD28*AE28*AF28 -> 360 | AH28: =AC28+AG28 -> 520 | AI28: =F28+G28+P28+Y28+AH28 -> 12679.9 | AJ28: =AI28/E28 -> 0.43993824 | AK28: =(E28-AI28)*$AK$15 -> 1775.631 | AL28: 0 | AM28: 0 | AN28: 0 | AO28: 0 | AP28: 0.031700668 | AQ28: =AP28*E28 -> 913.67664 | AR28: =AL28+AM28+AN28+AO28+AQ28 -> 913.67664 | AS28: =AK28+AR28 -> 2689.3076 | AT28: =E28-AS28 -> 26132.692
B29: 04/24 | C29: 79 | D29: SHCES 509 BL B | E29: 5392 | F29: 0 | G29: 0 | H29: 1 | I29: 19.53 | J29: 26 | K29: =H29*I29*J29 -> 507.78 | L29: 0 | M29: 0 | N29: 0 | O29: =L29*M29*N29 -> 0 | P29: =K29+O29 -> 507.78 | Q29: 1 | R29: 42.5 | S29: 26 | T29: =Q29*R29*S29 -> 1105 | U29: 0 | V29: 0 | W29: 0 | X29: =U29*V29*W29 -> 0 | Y29: =T29+X29 -> 1105 | Z29: 0 | AA29: 0 | AB29: 0 | AC29: =Z29*AA29*AB29 -> 0 | AD29: 0 | AE29: 0 | AF29: 0 | AG29: =AD29*AE29*AF29 -> 0 | AH29: =AC29+AG29 -> 0 | AI29: =F29+G29+P29+Y29+AH29 -> 1612.78 | AJ29: =AI29/E29 -> 0.29910608 | AK29: =(E29-AI29)*$AK$15 -> 415.7142 | AL29: 0 | AM29: 0 | AN29: 0 | AO29: 0 | AP29: 0.031700668 | AQ29: =AP29*E29 -> 170.93 | AR29: =AL29+AM29+AN29+AO29+AQ29 -> 170.93 | AS29: =AK29+AR29 -> 586.6442 | AT29: =E29-AS29 -> 4805.3558
B30: 04/24 | C30: 80 | D30: RPR 01 | E30: 11906 | F30: 1977.4 | G30: 2040 | H30: 2 | I30: 16 | J30: 26 | K30: =H30*I30*J30 -> 832 | L30: 0 | M30: 0 | N30: 0 | O30: =L30*M30*N30 -> 0 | P30: =K30+O30 -> 832 | Q30: 2 | R30: 42.5 | S30: 26 | T30: =Q30*R30*S30 -> 2210 | U30: 0 | V30: 0 | W30: 0 | X30: =U30*V30*W30 -> 0 | Y30: =T30+X30 -> 2210 | Z30: 2 | AA30: 80 | AB30: 1 | AC30: =Z30*AA30*AB30 -> 160 | AD30: 0 | AE30: 0 | AF30: 0 | AG30: =AD30*AE30*AF30 -> 0 | AH30: =AC30+AG30 -> 160 | AI30: =F30+G30+P30+Y30+AH30 -> 7219.4 | AJ30: =AI30/E30 -> 0.60636654 | AK30: =(E30-AI30)*$AK$15 -> 515.526 | AL30: 0 | AM30: 0 | AN30: 0 | AO30: 0 | AP30: 0.031700668 | AQ30: =AP30*E30 -> 377.42815 | AR30: =AL30+AM30+AN30+AO30+AQ30 -> 377.42815 | AS30: =AK30+AR30 -> 892.95415 | AT30: =E30-AS30 -> 11013.046
